Workbook

Sheet Instructions
D3: ANNUAL BUDGET PLANNER
D4: Your Complete Financial Planning Toolkit
D6: GETTING STARTED
D7: 1. Navigate to the "Easy Setup" tab to configure your budget
D8: 2. Enter your currency symbol, income sources, and expense categories
D9: 3. Set your budget amounts for each category
D10: 4. Monthly tabs will reference your setup data
D12: HOW TO USE EACH TAB
D13: Easy Setup - Configure your personal information and budget categories
D14: All-in-One Dashboard - View your financial overview with charts and KPIs
D15: Annual Totals - See yearly summary across all months
D16: Monthly Tabs (Jan-Dec) - Track income and expenses each month
... D36: Blush headers - Column labels

Sheet Easy Setup
B2: Budget Year 2026
B4: SETUP
B5: Instructions | D5: PERSONAL INFORMATION
B6: Easy Setup
D7: Currency Symbol: | E7: $
B8: DASHBOARDS | D8: Start Month: | E8: January
B9: All-in-One Dashboard | D9: Budget Period: | E9: Monthly
B10: Annual Totals
D11: INCOME SOURCES
B12: MONTHLY | D12: Source | E12: Monthly Amount
B13: January | D13: Salary | E13: 5000
B14: February | D14: Side Hustle | E14: 500
B15: March | D15: Freelance | E15: 800
B16: April | D16: Investments | E16: 200
B17: May | D17: Other | E17: 0
B18: June | D18: TOTAL INCOME | E18: =SUM(E13:E17)
B19: July
B20: August | D20: EXPENSE CATEGORIES
B21: September | D21: Category | E21: Monthly Budget | F21: Priority
B22: October | D22: Housing | E22: 1500 | F22: Need
B23: November | D23: Utilities | E23: 200 | F23: Need
B24: December | D24: Groceries | E24: 400 | F24: Need
D25: Transportation | E25: 300 | F25: Need
B26: WEALTH | D26: Insurance | E26: 150 | F26: Need
B27: 50-30-20 | D27: Healthcare | E27: 100 | F27: Need
B28: Expense Dist | D28: Entertainment | E28: 150 | F28: Want
B29: Sinking Funds | D29: Dining Out | E29: 200 | F29: Want
B30: Debt Calc | D30: Shopping | E30: 150 | F30: Want
B31: Net Worth | D31: Subscriptions | E31: 50 | F31: Want
D32: Savings | E32: 500 | F32: Savings
D33: Debt Payments | E33: 300 | F33: Need
D34: Education | E34: 100 | F34: Want
D35: Personal Care | E35: 75 | F35: Want
D36: Gifts | E36: 50 | F36: Want
D37: Miscellaneous | E37: 100 | F37: Want
D38: TOTAL EXPENSES | E38: =SUM(E22:E37)

Sheet All-in-One Dashboard
AH1: Category | AI1: Amount
B2: Budget Year 2026 | AH2: Housing | AI2: 1500
AH3: Utilities | AI3: 200
B4: SETUP | AH4: Groceries | AI4: 400
B5: Instructions | D5: FINANCIAL OVERVIEW | AH5: Transportation | AI5: 300
B6: Easy Setup | AH6: Insurance | AI6: 150
D7: =SUM(January!E8:E12,February!E8:E12,March!E8:E12,April!E8:E12,May!E8:E12,June!E8:E12,July!E8:E12,August!E8:E12,September!E8:E12,October!E8:E12,November!E8:E12,December!E8:E12) | H7: =SUM(January!E19:E26,February!E19:E26,March!E19:E26,April!E19:E26,May!E19:E26,June!E19:E26,July!E19:E26,August!E19:E26,September!E19:E26,October!E19:E26,November!E19:E26,December!E19:E26)+SUM(January!H33:H62,February!H33:H62,March!H33:H62,April!H33:H62,May!H33:H62,June!H33:H62,July!H33:H62,August!H33:H62,September!H33:H62,October!H33:H62,November!H33:H62,December!H33:H62) | L7: =D7-H7 | P7: =IF(D7>0,L7/D7,0) | AH7: Healthcare | AI7: 100
B8: DASHBOARDS | AH8: Entertainment | AI8: 150
B9: All-in-One Dashboard | D9: Total Income | H9: Total Expenses | L9: Net Savings | P9: Savings Rate | AH9: Dining Out | AI9: 200
B10: Annual Totals
B12: MONTHLY | AH12: Month | AI12: Income | AJ12: Expenses
B13: January | AH13: Jan | AI13: =SUM('January'!E8:E12) | AJ13: =SUM('January'!E19:E26)+SUM('January'!H33:H62)
B14: February | AH14: Feb | AI14: =SUM('February'!E8:E12) | AJ14: =SUM('February'!E19:E26)+SUM('February'!H33:H62)
B15: March | AH15: Mar | AI15: =SUM('March'!E8:E12) | AJ15: =SUM('March'!E19:E26)+SUM('March'!H33:H62)
B16: April | AH16: Apr | AI16: =SUM('April'!E8:E12) | AJ16: =SUM('April'!E19:E26)+SUM('April'!H33:H62)
B17: May | AH17: May | AI17: =SUM('May'!E8:E12) | AJ17: =SUM('May'!E19:E26)+SUM('May'!H33:H62)
B18: June | AH18: Jun | AI18: =SUM('June'!E8:E12) | AJ18: =SUM('June'!E19:E26)+SUM('June'!H33:H62)
B19: July | AH19: Jul | AI19: =SUM('July'!E8:E12) | AJ19: =SUM('July'!E19:E26)+SUM('July'!H33:H62)
B20: August | AH20: Aug | AI20: =SUM('August'!E8:E12) | AJ20: =SUM('August'!E19:E26)+SUM('August'!H33:H62)
B21: September | AH21: Sep | AI21: =SUM('September'!E8:E12) | AJ21: =SUM('September'!E19:E26)+SUM('September'!H33:H62)
B22: October | AH22: Oct | AI22: =SUM('October'!E8:E12) | AJ22: =SUM('October'!E19:E26)+SUM('October'!H33:H62)
B23: November | AH23: Nov | AI23: =SUM('November'!E8:E12) | AJ23: =SUM('November'!E19:E26)+SUM('November'!H33:H62)
B24: December | AH24: Dec | AI24: =SUM('December'!E8:E12) | AJ24: =SUM('December'!E19:E26)+SUM('December'!H33:H62)
B26: WEALTH | AH26: Month | AI26: Cumulative Savings
B27: 50-30-20 | AH27: Jan | AI27: =AI13-AJ13
B28: Expense Dist | AH28: Feb | AI28: =AI27+(AI28-AJ28)
B29: Sinking Funds | AH29: Mar | AI29: =AI28+(AI29-AJ29)
B30: Debt Calc | AH30: Apr | AI30: =AI29+(AI30-AJ30)
B31: Net Worth | AH31: May | AI31: =AI30+(AI31-AJ31)
AH32: Jun | AI32: =AI31+(AI32-AJ32)
AH33: Jul | AI33: =AI32+(AI33-AJ33)
AH34: Aug | AI34: =AI33+(AI34-AJ34)
AH35: Sep | AI35: =AI34+(AI35-AJ35)
AH36: Oct | AI36: =AI35+(AI36-AJ36)
AH37: Nov | AI37: =AI36+(AI37-AJ37)
AH38: Dec | AI38: =AI37+(AI38-AJ38)

Sheet Annual Totals
B2: Budget Year 2026
B4: SETUP
B5: Instructions | D5: ANNUAL BUDGET SUMMARY
B6: Easy Setup
D7: Category | E7: Jan | F7: Feb | G7: Mar | H7: Apr | I7: May | J7: Jun | K7: Jul | L7: Aug | M7: Sep | N7: Oct | O7: Nov | P7: Dec | Q7: TOTAL
B8: DASHBOARDS | D8: Housing | E8: =SUMIF('January'!D19:D26,D8,'January'!E19:E26) | F8: =SUMIF('February'!D19:D26,D8,'February'!E19:E26) | G8: =SUMIF('March'!D19:D26,D8,'March'!E19:E26) | H8: =SUMIF('April'!D19:D26,D8,'April'!E19:E26) | I8: =SUMIF('May'!D19:D26,D8,'May'!E19:E26) | J8: =SUMIF('June'!D19:D26,D8,'June'!E19:E26) | K8: =SUMIF('July'!D19:D26,D8,'July'!E19:E26) | L8: =SUMIF('August'!D19:D26,D8,'August'!E19:E26) | M8: =SUMIF('September'!D19:D26,D8,'September'!E19:E26) | N8: =SUMIF('October'!D19:D26,D8,'October'!E19:E26) | O8: =SUMIF('November'!D19:D26,D8,'November'!E19:E26) | P8: =SUMIF('December'!D19:D26,D8,'December'!E19:E26) | Q8: =SUM(E8:P8)
B9: All-in-One Dashboard | D9: Utilities | E9: =SUMIF('January'!D19:D26,D9,'January'!E19:E26) | F9: =SUMIF('February'!D19:D26,D9,'February'!E19:E26) | G9: =SUMIF('March'!D19:D26,D9,'March'!E19:E26) | H9: =SUMIF('April'!D19:D26,D9,'April'!E19:E26) | I9: =SUMIF('May'!D19:D26,D9,'May'!E19:E26) | J9: =SUMIF('June'!D19:D26,D9,'June'!E19:E26) | K9: =SUMIF('July'!D19:D26,D9,'July'!E19:E26) | L9: =SUMIF('August'!D19:D26,D9,'August'!E19:E26) | M9: =SUMIF('September'!D19:D26,D9,'September'!E19:E26) | N9: =SUMIF('October'!D19:D26,D9,'October'!E19:E26) | O9: =SUMIF('November'!D19:D26,D9,'November'!E19:E26) | P9: =SUMIF('December'!D19:D26,D9,'December'!E19:E26) | Q9: =SUM(E9:P9)
B10: Annual Totals | D10: Groceries | E10: =SUMIF('January'!D19:D26,D10,'January'!E19:E26) | F10: =SUMIF('February'!D19:D26,D10,'February'!E19:E26) | G10: =SUMIF('March'!D19:D26,D10,'March'!E19:E26) | H10: =SUMIF('April'!D19:D26,D10,'April'!E19:E26) | I10: =SUMIF('May'!D19:D26,D10,'May'!E19:E26) | J10: =SUMIF('June'!D19:D26,D10,'June'!E19:E26) | K10: =SUMIF('July'!D19:D26,D10,'July'!E19:E26) | L10: =SUMIF('August'!D19:D26,D10,'August'!E19:E26) | M10: =SUMIF('September'!D19:D26,D10,'September'!E19:E26) | N10: =SUMIF('October'!D19:D26,D10,'October'!E19:E26) | O10: =SUMIF('November'!D19:D26,D10,'November'!E19:E26) | P10: =SUMIF('December'!D19:D26,D10,'December'!E19:E26) | Q10: =SUM(E10:P10)
D11: Transportation | E11: =SUMIF('January'!D19:D26,D11,'January'!E19:E26) | F11: =SUMIF('February'!D19:D26,D11,'February'!E19:E26) | G11: =SUMIF('March'!D19:D26,D11,'March'!E19:E26) | H11: =SUMIF('April'!D19:D26,D11,'April'!E19:E26) | I11: =SUMIF('May'!D19:D26,D11,'May'!E19:E26) | J11: =SUMIF('June'!D19:D26,D11,'June'!E19:E26) | K11: =SUMIF('July'!D19:D26,D11,'July'!E19:E26) | L11: =SUMIF('August'!D19:D26,D11,'August'!E19:E26) | M11: =SUMIF('September'!D19:D26,D11,'September'!E19:E26) | N11: =SUMIF('October'!D19:D26,D11,'October'!E19:E26) | O11: =SUMIF('November'!D19:D26,D11,'November'!E19:E26) | P11: =SUMIF('December'!D19:D26,D11,'December'!E19:E26) | Q11: =SUM(E11:P11)
B12: MONTHLY | D12: Insurance | E12: =SUMIF('January'!D19:D26,D12,'January'!E19:E26) | F12: =SUMIF('February'!D19:D26,D12,'February'!E19:E26) | G12: =SUMIF('March'!D19:D26,D12,'March'!E19:E26) | H12: =SUMIF('April'!D19:D26,D12,'April'!E19:E26) | I12: =SUMIF('May'!D19:D26,D12,'May'!E19:E26) | J12: =SUMIF('June'!D19:D26,D12,'June'!E19:E26) | K12: =SUMIF('July'!D19:D26,D12,'July'!E19:E26) | L12: =SUMIF('August'!D19:D26,D12,'August'!E19:E26) | M12: =SUMIF('September'!D19:D26,D12,'September'!E19:E26) | N12: =SUMIF('October'!D19:D26,D12,'October'!E19:E26) | O12: =SUMIF('November'!D19:D26,D12,'November'!E19:E26) | P12: =SUMIF('December'!D19:D26,D12,'December'!E19:E26) | Q12: =SUM(E12:P12)
B13: January | D13: Healthcare | E13: =SUMIF('January'!D19:D26,D13,'January'!E19:E26) | F13: =SUMIF('February'!D19:D26,D13,'February'!E19:E26) | G13: =SUMIF('March'!D19:D26,D13,'March'!E19:E26) | H13: =SUMIF('April'!D19:D26,D13,'April'!E19:E26) | I13: =SUMIF('May'!D19:D26,D13,'May'!E19:E26) | J13: =SUMIF('June'!D19:D26,D13,'June'!E19:E26) | K13: =SUMIF('July'!D19:D26,D13,'July'!E19:E26) | L13: =SUMIF('August'!D19:D26,D13,'August'!E19:E26) | M13: =SUMIF('September'!D19:D26,D13,'September'!E19:E26) | N13: =SUMIF('October'!D19:D26,D13,'October'!E19:E26) | O13: =SUMIF('November'!D19:D26,D13,'November'!E19:E26) | P13: =SUMIF('December'!D19:D26,D13,'December'!E19:E26) | Q13: =SUM(E13:P13)
B14: February | D14: Entertainment | E14: =SUMIF('January'!D19:D26,D14,'January'!E19:E26) | F14: =SUMIF('February'!D19:D26,D14,'February'!E19:E26) | G14: =SUMIF('March'!D19:D26,D14,'March'!E19:E26) | H14: =SUMIF('April'!D19:D26,D14,'April'!E19:E26) | I14: =SUMIF('May'!D19:D26,D14,'May'!E19:E26) | J14: =SUMIF('June'!D19:D26,D14,'June'!E19:E26) | K14: =SUMIF('July'!D19:D26,D14,'July'!E19:E26) | L14: =SUMIF('August'!D19:D26,D14,'August'!E19:E26) | M14: =SUMIF('September'!D19:D26,D14,'September'!E19:E26) | N14: =SUMIF('October'!D19:D26,D14,'October'!E19:E26) | O14: =SUMIF('November'!D19:D26,D14,'November'!E19:E26) | P14: =SUMIF('December'!D19:D26,D14,'December'!E19:E26) | Q14: =SUM(E14:P14)
B15: March | D15: Dining Out | E15: =SUMIF('January'!D19:D26,D15,'January'!E19:E26) | F15: =SUMIF('February'!D19:D26,D15,'February'!E19:E26) | G15: =SUMIF('March'!D19:D26,D15,'March'!E19:E26) | H15: =SUMIF('April'!D19:D26,D15,'April'!E19:E26) | I15: =SUMIF('May'!D19:D26,D15,'May'!E19:E26) | J15: =SUMIF('June'!D19:D26,D15,'June'!E19:E26) | K15: =SUMIF('July'!D19:D26,D15,'July'!E19:E26) | L15: =SUMIF('August'!D19:D26,D15,'August'!E19:E26) | M15: =SUMIF('September'!D19:D26,D15,'September'!E19:E26) | N15: =SUMIF('October'!D19:D26,D15,'October'!E19:E26) | O15: =SUMIF('November'!D19:D26,D15,'November'!E19:E26) | P15: =SUMIF('December'!D19:D26,D15,'December'!E19:E26) | Q15: =SUM(E15:P15)
B16: April | D16: Shopping | E16: =SUMIF('January'!D19:D26,D16,'January'!E19:E26) | F16: =SUMIF('February'!D19:D26,D16,'February'!E19:E26) | G16: =SUMIF('March'!D19:D26,D16,'March'!E19:E26) | H16: =SUMIF('April'!D19:D26,D16,'April'!E19:E26) | I16: =SUMIF('May'!D19:D26,D16,'May'!E19:E26) | J16: =SUMIF('June'!D19:D26,D16,'June'!E19:E26) | K16: =SUMIF('July'!D19:D26,D16,'July'!E19:E26) | L16: =SUMIF('August'!D19:D26,D16,'August'!E19:E26) | M16: =SUMIF('September'!D19:D26,D16,'September'!E19:E26) | N16: =SUMIF('October'!D19:D26,D16,'October'!E19:E26) | O16: =SUMIF('November'!D19:D26,D16,'November'!E19:E26) | P16: =SUMIF('December'!D19:D26,D16,'December'!E19:E26) | Q16: =SUM(E16:P16)
B17: May | D17: Subscriptions | E17: =SUMIF('January'!D19:D26,D17,'January'!E19:E26) | F17: =SUMIF('February'!D19:D26,D17,'February'!E19:E26) | G17: =SUMIF('March'!D19:D26,D17,'March'!E19:E26) | H17: =SUMIF('April'!D19:D26,D17,'April'!E19:E26) | I17: =SUMIF('May'!D19:D26,D17,'May'!E19:E26) | J17: =SUMIF('June'!D19:D26,D17,'June'!E19:E26) | K17: =SUMIF('July'!D19:D26,D17,'July'!E19:E26) | L17: =SUMIF('August'!D19:D26,D17,'August'!E19:E26) | M17: =SUMIF('September'!D19:D26,D17,'September'!E19:E26) | N17: =SUMIF('October'!D19:D26,D17,'October'!E19:E26) | O17: =SUMIF('November'!D19:D26,D17,'November'!E19:E26) | P17: =SUMIF('December'!D19:D26,D17,'December'!E19:E26) | Q17: =SUM(E17:P17)
B18: June | D18: Savings | E18: =SUMIF('January'!D19:D26,D18,'January'!E19:E26) | F18: =SUMIF('February'!D19:D26,D18,'February'!E19:E26) | G18: =SUMIF('March'!D19:D26,D18,'March'!E19:E26) | H18: =SUMIF('April'!D19:D26,D18,'April'!E19:E26) | I18: =SUMIF('May'!D19:D26,D18,'May'!E19:E26) | J18: =SUMIF('June'!D19:D26,D18,'June'!E19:E26) | K18: =SUMIF('July'!D19:D26,D18,'July'!E19:E26) | L18: =SUMIF('August'!D19:D26,D18,'August'!E19:E26) | M18: =SUMIF('September'!D19:D26,D18,'September'!E19:E26) | N18: =SUMIF('October'!D19:D26,D18,'October'!E19:E26) | O18: =SUMIF('November'!D19:D26,D18,'November'!E19:E26) | P18: =SUMIF('December'!D19:D26,D18,'December'!E19:E26) | Q18: =SUM(E18:P18)
B19: July | D19: Debt Payments | E19: =SUMIF('January'!D19:D26,D19,'January'!E19:E26) | F19: =SUMIF('February'!D19:D26,D19,'February'!E19:E26) | G19: =SUMIF('March'!D19:D26,D19,'March'!E19:E26) | H19: =SUMIF('April'!D19:D26,D19,'April'!E19:E26) | I19: =SUMIF('May'!D19:D26,D19,'May'!E19:E26) | J19: =SUMIF('June'!D19:D26,D19,'June'!E19:E26) | K19: =SUMIF('July'!D19:D26,D19,'July'!E19:E26) | L19: =SUMIF('August'!D19:D26,D19,'August'!E19:E26) | M19: =SUMIF('September'!D19:D26,D19,'September'!E19:E26) | N19: =SUMIF('October'!D19:D26,D19,'October'!E19:E26) | O19: =SUMIF('November'!D19:D26,D19,'November'!E19:E26) | P19: =SUMIF('December'!D19:D26,D19,'December'!E19:E26) | Q19: =SUM(E19:P19)
B20: August | D20: Education | E20: =SUMIF('January'!D19:D26,D20,'January'!E19:E26) | F20: =SUMIF('February'!D19:D26,D20,'February'!E19:E26) | G20: =SUMIF('March'!D19:D26,D20,'March'!E19:E26) | H20: =SUMIF('April'!D19:D26,D20,'April'!E19:E26) | I20: =SUMIF('May'!D19:D26,D20,'May'!E19:E26) | J20: =SUMIF('June'!D19:D26,D20,'June'!E19:E26) | K20: =SUMIF('July'!D19:D26,D20,'July'!E19:E26) | L20: =SUMIF('August'!D19:D26,D20,'August'!E19:E26) | M20: =SUMIF('September'!D19:D26,D20,'September'!E19:E26) | N20: =SUMIF('October'!D19:D26,D20,'October'!E19:E26) | O20: =SUMIF('November'!D19:D26,D20,'November'!E19:E26) | P20: =SUMIF('December'!D19:D26,D20,'December'!E19:E26) | Q20: =SUM(E20:P20)
B21: September | D21: Personal Care | E21: =SUMIF('January'!D19:D26,D21,'January'!E19:E26) | F21: =SUMIF('February'!D19:D26,D21,'February'!E19:E26) | G21: =SUMIF('March'!D19:D26,D21,'March'!E19:E26) | H21: =SUMIF('April'!D19:D26,D21,'April'!E19:E26) | I21: =SUMIF('May'!D19:D26,D21,'May'!E19:E26) | J21: =SUMIF('June'!D19:D26,D21,'June'!E19:E26) | K21: =SUMIF('July'!D19:D26,D21,'July'!E19:E26) | L21: =SUMIF('August'!D19:D26,D21,'August'!E19:E26) | M21: =SUMIF('September'!D19:D26,D21,'September'!E19:E26) | N21: =SUMIF('October'!D19:D26,D21,'October'!E19:E26) | O21: =SUMIF('November'!D19:D26,D21,'November'!E19:E26) | P21: =SUMIF('December'!D19:D26,D21,'December'!E19:E26) | Q21: =SUM(E21:P21)
B22: October | D22: Gifts | E22: =SUMIF('January'!D19:D26,D22,'January'!E19:E26) | F22: =SUMIF('February'!D19:D26,D22,'February'!E19:E26) | G22: =SUMIF('March'!D19:D26,D22,'March'!E19:E26) | H22: =SUMIF('April'!D19:D26,D22,'April'!E19:E26) | I22: =SUMIF('May'!D19:D26,D22,'May'!E19:E26) | J22: =SUMIF('June'!D19:D26,D22,'June'!E19:E26) | K22: =SUMIF('July'!D19:D26,D22,'July'!E19:E26) | L22: =SUMIF('August'!D19:D26,D22,'August'!E19:E26) | M22: =SUMIF('September'!D19:D26,D22,'September'!E19:E26) | N22: =SUMIF('October'!D19:D26,D22,'October'!E19:E26) | O22: =SUMIF('November'!D19:D26,D22,'November'!E19:E26) | P22: =SUMIF('December'!D19:D26,D22,'December'!E19:E26) | Q22: =SUM(E22:P22)
B23: November | D23: Miscellaneous | E23: =SUMIF('January'!D19:D26,D23,'January'!E19:E26) | F23: =SUMIF('February'!D19:D26,D23,'February'!E19:E26) | G23: =SUMIF('March'!D19:D26,D23,'March'!E19:E26) | H23: =SUMIF('April'!D19:D26,D23,'April'!E19:E26) | I23: =SUMIF('May'!D19:D26,D23,'May'!E19:E26) | J23: =SUMIF('June'!D19:D26,D23,'June'!E19:E26) | K23: =SUMIF('July'!D19:D26,D23,'July'!E19:E26) | L23: =SUMIF('August'!D19:D26,D23,'August'!E19:E26) | M23: =SUMIF('September'!D19:D26,D23,'September'!E19:E26) | N23: =SUMIF('October'!D19:D26,D23,'October'!E19:E26) | O23: =SUMIF('November'!D19:D26,D23,'November'!E19:E26) | P23: =SUMIF('December'!D19:D26,D23,'December'!E19:E26) | Q23: =SUM(E23:P23)
B24: December | D24: TOTAL | E24: =SUM(E8:E23) | F24: =SUM(F8:F23) | G24: =SUM(G8:G23) | H24: =SUM(H8:H23) | I24: =SUM(I8:I23) | J24: =SUM(J8:J23) | K24: =SUM(K8:K23) | L24: =SUM(L8:L23) | ... Q24: =SUM(Q8:Q23)
B26: WEALTH
B27: 50-30-20
B28: Expense Dist
B29: Sinking Funds
B30: Debt Calc
B31: Net Worth

Sheet January
B2: Budget Year 2026
B4: SETUP
B5: Instructions | D5: JANUARY INCOME
B6: Easy Setup
D7: Source | E7: Amount | F7: Date Received
B8: DASHBOARDS | D8: Salary | E8: 5000 | F8: 46023
B9: All-in-One Dashboard | D9: Side Hustle | E9: 500 | F9: 46028
B10: Annual Totals | D10: Freelance | E10: 800 | F10: 46033
D11: Investments | E11: 200 | F11: 46038
B12: MONTHLY | D12: Other | E12: 0
B13: January | D13: TOTAL INCOME | E13: =SUM(E8:E12)
B14: February
B15: March | D15: FIXED EXPENSES
B16: April
B17: May | D17: Category | E17: Budget | F17: Actual | G17: Difference
B18: June | D18: Housing | E18: 1500 | F18: 1500 | G18: =E18-F18
B19: July | D19: Utilities | E19: 200 | F19: 185 | G19: =E19-F19
B20: August | D20: Insurance | E20: 150 | F20: 150 | G20: =E20-F20
B21: September | D21: Transportation | E21: 300 | F21: 275 | G21: =E21-F21
B22: October | D22: Healthcare | E22: 100 | F22: 80 | G22: =E22-F22
B23: November | D23: Debt Payments | E23: 300 | F23: 300 | G23: =E23-F23
B24: December | D24: Subscriptions | E24: 50 | F24: 55 | G24: =E24-F24
D25: Education | E25: 100 | F25: 100 | G25: =E25-F25
B26: WEALTH | D26: TOTAL FIXED | E26: =SUM(E18:E25) | F26: =SUM(F18:F25) | G26: =E26-F26
B27: 50-30-20
B28: Expense Dist | D28: VARIABLE EXPENSES
B29: Sinking Funds
B30: Debt Calc | D30: Date | E30: Category | F30: Description | G30: Amount | H30: Amount
B31: Net Worth | D31: 46025 | E31: Groceries | F31: Weekly groceries | H31: 120
D32: 46027 | E32: Dining Out | F32: Restaurant dinner | H32: 65
D33: 46030 | E33: Entertainment | F33: Movie tickets | H33: 35
D34: 46032 | E34: Shopping | F34: New shoes | H34: 85
D35: 46034 | E35: Personal Care | F35: Haircut | H35: 40
D36: 46037 | E36: Groceries | F36: Weekly groceries | H36: 95
D37: 46040 | E37: Dining Out | F37: Lunch meeting | H37: 28
D38: 46044 | E38: Groceries | F38: Weekly groceries | H38: 110
D39: 46047 | E39: Gifts | F39: Birthday gift | H39: 50
D40: 46050 | E40: Groceries | F40: Weekly groceries | H40: 105
D61: TOTAL VARIABLE | H61: =SUM(H31:H60)
D63: MONTHLY SUMMARY
...

Sheet February
B2: Budget Year 2026
B4: SETUP
B5: Instructions | D5: FEBRUARY INCOME
B6: Easy Setup
D7: Source | E7: Amount | F7: Date Received
B8: DASHBOARDS | D8: Salary
B9: All-in-One Dashboard | D9: Side Hustle
B10: Annual Totals | D10: Freelance
D11: Investments
B12: MONTHLY | D12: Other
B13: January | D13: TOTAL INCOME | E13: =SUM(E8:E12)
B14: February
B15: March | D15: FIXED EXPENSES
B16: April
B17: May | D17: Category | E17: Budget | F17: Actual | G17: Difference
B18: June | G18: =E18-F18
B19: July | G19: =E19-F19
B20: August | G20: =E20-F20
B21: September | G21: =E21-F21
B22: October | G22: =E22-F22
B23: November | G23: =E23-F23
B24: December | G24: =E24-F24
G25: =E25-F25
B26: WEALTH | D26: TOTAL FIXED | E26: =SUM(E18:E25) | F26: =SUM(F18:F25) | G26: =E26-F26
B27: 50-30-20
B28: Expense Dist | D28: VARIABLE EXPENSES
B29: Sinking Funds
B30: Debt Calc | D30: Date | E30: Category | F30: Description | G30: Amount | H30: Amount
B31: Net Worth
D61: TOTAL VARIABLE | H61: =SUM(H31:H60)
D63: MONTHLY SUMMARY
D65: Total Income | E65: =E13
D66: Total Fixed Expenses | E66: =F26
D67: Total Variable Expenses | E67: =H61
D68: NET (Income - Expenses) | E68: =E13-F26-H61

Sheet March
B2: Budget Year 2026
B4: SETUP
B5: Instructions | D5: MARCH INCOME
B6: Easy Setup
D7: Source | E7: Amount | F7: Date Received
B8: DASHBOARDS | D8: Salary
B9: All-in-One Dashboard | D9: Side Hustle
B10: Annual Totals | D10: Freelance
D11: Investments
B12: MONTHLY | D12: Other
B13: January | D13: TOTAL INCOME | E13: =SUM(E8:E12)
B14: February
B15: March | D15: FIXED EXPENSES
B16: April
B17: May | D17: Category | E17: Budget | F17: Actual | G17: Difference
B18: June | G18: =E18-F18
B19: July | G19: =E19-F19
B20: August | G20: =E20-F20
B21: September | G21: =E21-F21
B22: October | G22: =E22-F22
B23: November | G23: =E23-F23
B24: December | G24: =E24-F24
G25: =E25-F25
B26: WEALTH | D26: TOTAL FIXED | E26: =SUM(E18:E25) | F26: =SUM(F18:F25) | G26: =E26-F26
B27: 50-30-20
B28: Expense Dist | D28: VARIABLE EXPENSES
B29: Sinking Funds
B30: Debt Calc | D30: Date | E30: Category | F30: Description | G30: Amount | H30: Amount
B31: Net Worth
D61: TOTAL VARIABLE | H61: =SUM(H31:H60)
D63: MONTHLY SUMMARY
D65: Total Income | E65: =E13
D66: Total Fixed Expenses | E66: =F26
D67: Total Variable Expenses | E67: =H61
D68: NET (Income - Expenses) | E68: =E13-F26-H61

Sheet April
B2: Budget Year 2026
B4: SETUP
B5: Instructions | D5: APRIL INCOME
B6: Easy Setup
D7: Source | E7: Amount | F7: Date Received
B8: DASHBOARDS | D8: Salary
B9: All-in-One Dashboard | D9: Side Hustle
B10: Annual Totals | D10: Freelance
D11: Investments
B12: MONTHLY | D12: Other
B13: January | D13: TOTAL INCOME | E13: =SUM(E8:E12)
B14: February
B15: March | D15: FIXED EXPENSES
B16: April
B17: May | D17: Category | E17: Budget | F17: Actual | G17: Difference
B18: June | G18: =E18-F18
B19: July | G19: =E19-F19
B20: August | G20: =E20-F20
B21: September | G21: =E21-F21
B22: October | G22: =E22-F22
B23: November | G23: =E23-F23
B24: December | G24: =E24-F24
G25: =E25-F25
B26: WEALTH | D26: TOTAL FIXED | E26: =SUM(E18:E25) | F26: =SUM(F18:F25) | G26: =E26-F26
B27: 50-30-20
B28: Expense Dist | D28: VARIABLE EXPENSES
B29: Sinking Funds
B30: Debt Calc | D30: Date | E30: Category | F30: Description | G30: Amount | H30: Amount
B31: Net Worth
D61: TOTAL VARIABLE | H61: =SUM(H31:H60)
D63: MONTHLY SUMMARY
D65: Total Income | E65: =E13
D66: Total Fixed Expenses | E66: =F26
D67: Total Variable Expenses | E67: =H61
D68: NET (Income - Expenses) | E68: =E13-F26-H61

Sheet May
B2: Budget Year 2026
B4: SETUP
B5: Instructions | D5: MAY INCOME
B6: Easy Setup
D7: Source | E7: Amount | F7: Date Received
B8: DASHBOARDS | D8: Salary
B9: All-in-One Dashboard | D9: Side Hustle
B10: Annual Totals | D10: Freelance
D11: Investments
B12: MONTHLY | D12: Other
B13: January | D13: TOTAL INCOME | E13: =SUM(E8:E12)
B14: February
B15: March | D15: FIXED EXPENSES
B16: April
B17: May | D17: Category | E17: Budget | F17: Actual | G17: Difference
B18: June | G18: =E18-F18
B19: July | G19: =E19-F19
B20: August | G20: =E20-F20
B21: September | G21: =E21-F21
B22: October | G22: =E22-F22
B23: November | G23: =E23-F23
B24: December | G24: =E24-F24
G25: =E25-F25
B26: WEALTH | D26: TOTAL FIXED | E26: =SUM(E18:E25) | F26: =SUM(F18:F25) | G26: =E26-F26
B27: 50-30-20
B28: Expense Dist | D28: VARIABLE EXPENSES
B29: Sinking Funds
B30: Debt Calc | D30: Date | E30: Category | F30: Description | G30: Amount | H30: Amount
B31: Net Worth
D61: TOTAL VARIABLE | H61: =SUM(H31:H60)
D63: MONTHLY SUMMARY
D65: Total Income | E65: =E13
D66: Total Fixed Expenses | E66: =F26
D67: Total Variable Expenses | E67: =H61
D68: NET (Income - Expenses) | E68: =E13-F26-H61

Sheet June
B2: Budget Year 2026
B4: SETUP
B5: Instructions | D5: JUNE INCOME
B6: Easy Setup
D7: Source | E7: Amount | F7: Date Received
B8: DASHBOARDS | D8: Salary
B9: All-in-One Dashboard | D9: Side Hustle
B10: Annual Totals | D10: Freelance
D11: Investments
B12: MONTHLY | D12: Other
B13: January | D13: TOTAL INCOME | E13: =SUM(E8:E12)
B14: February
B15: March | D15: FIXED EXPENSES
B16: April
B17: May | D17: Category | E17: Budget | F17: Actual | G17: Difference
B18: June | G18: =E18-F18
B19: July | G19: =E19-F19
B20: August | G20: =E20-F20
B21: September | G21: =E21-F21
B22: October | G22: =E22-F22
B23: November | G23: =E23-F23
B24: December | G24: =E24-F24
G25: =E25-F25
B26: WEALTH | D26: TOTAL FIXED | E26: =SUM(E18:E25) | F26: =SUM(F18:F25) | G26: =E26-F26
B27: 50-30-20
B28: Expense Dist | D28: VARIABLE EXPENSES
B29: Sinking Funds
B30: Debt Calc | D30: Date | E30: Category | F30: Description | G30: Amount | H30: Amount
B31: Net Worth
D61: TOTAL VARIABLE | H61: =SUM(H31:H60)
D63: MONTHLY SUMMARY
D65: Total Income | E65: =E13
D66: Total Fixed Expenses | E66: =F26
D67: Total Variable Expenses | E67: =H61
D68: NET (Income - Expenses) | E68: =E13-F26-H61

Sheet July
B2: Budget Year 2026
B4: SETUP
B5: Instructions | D5: JULY INCOME
B6: Easy Setup
D7: Source | E7: Amount | F7: Date Received
B8: DASHBOARDS | D8: Salary
B9: All-in-One Dashboard | D9: Side Hustle
B10: Annual Totals | D10: Freelance
D11: Investments
B12: MONTHLY | D12: Other
B13: January | D13: TOTAL INCOME | E13: =SUM(E8:E12)
B14: February
B15: March | D15: FIXED EXPENSES
B16: April
B17: May | D17: Category | E17: Budget | F17: Actual | G17: Difference
B18: June | G18: =E18-F18
B19: July | G19: =E19-F19
B20: August | G20: =E20-F20
B21: September | G21: =E21-F21
B22: October | G22: =E22-F22
B23: November | G23: =E23-F23
B24: December | G24: =E24-F24
G25: =E25-F25
B26: WEALTH | D26: TOTAL FIXED | E26: =SUM(E18:E25) | F26: =SUM(F18:F25) | G26: =E26-F26
B27: 50-30-20
B28: Expense Dist | D28: VARIABLE EXPENSES
B29: Sinking Funds
B30: Debt Calc | D30: Date | E30: Category | F30: Description | G30: Amount | H30: Amount
B31: Net Worth
D61: TOTAL VARIABLE | H61: =SUM(H31:H60)
D63: MONTHLY SUMMARY
D65: Total Income | E65: =E13
D66: Total Fixed Expenses | E66: =F26
D67: Total Variable Expenses | E67: =H61
D68: NET (Income - Expenses) | E68: =E13-F26-H61

Sheet August
B2: Budget Year 2026
B4: SETUP
B5: Instructions | D5: AUGUST INCOME
B6: Easy Setup
D7: Source | E7: Amount | F7: Date Received
B8: DASHBOARDS | D8: Salary
B9: All-in-One Dashboard | D9: Side Hustle
B10: Annual Totals | D10: Freelance
D11: Investments
B12: MONTHLY | D12: Other
B13: January | D13: TOTAL INCOME | E13: =SUM(E8:E12)
B14: February
B15: March | D15: FIXED EXPENSES
B16: April
B17: May | D17: Category | E17: Budget | F17: Actual | G17: Difference
B18: June | G18: =E18-F18
B19: July | G19: =E19-F19
B20: August | G20: =E20-F20
B21: September | G21: =E21-F21
B22: October | G22: =E22-F22
B23: November | G23: =E23-F23
B24: December | G24: =E24-F24
G25: =E25-F25
B26: WEALTH | D26: TOTAL FIXED | E26: =SUM(E18:E25) | F26: =SUM(F18:F25) | G26: =E26-F26
B27: 50-30-20
B28: Expense Dist | D28: VARIABLE EXPENSES
B29: Sinking Funds
B30: Debt Calc | D30: Date | E30: Category | F30: Description | G30: Amount | H30: Amount
B31: Net Worth
D61: TOTAL VARIABLE | H61: =SUM(H31:H60)
D63: MONTHLY SUMMARY
D65: Total Income | E65: =E13
D66: Total Fixed Expenses | E66: =F26
D67: Total Variable Expenses | E67: =H61
D68: NET (Income - Expenses) | E68: =E13-F26-H61

Sheet September
B2: Budget Year 2026
B4: SETUP
B5: Instructions | D5: SEPTEMBER INCOME
B6: Easy Setup
D7: Source | E7: Amount | F7: Date Received
B8: DASHBOARDS | D8: Salary
B9: All-in-One Dashboard | D9: Side Hustle
B10: Annual Totals | D10: Freelance
D11: Investments
B12: MONTHLY | D12: Other
B13: January | D13: TOTAL INCOME | E13: =SUM(E8:E12)
B14: February
B15: March | D15: FIXED EXPENSES
B16: April
B17: May | D17: Category | E17: Budget | F17: Actual | G17: Difference
B18: June | G18: =E18-F18
B19: July | G19: =E19-F19
B20: August | G20: =E20-F20
B21: September | G21: =E21-F21
B22: October | G22: =E22-F22
B23: November | G23: =E23-F23
B24: December | G24: =E24-F24
G25: =E25-F25
B26: WEALTH | D26: TOTAL FIXED | E26: =SUM(E18:E25) | F26: =SUM(F18:F25) | G26: =E26-F26
B27: 50-30-20
B28: Expense Dist | D28: VARIABLE EXPENSES
B29: Sinking Funds
B30: Debt Calc | D30: Date | E30: Category | F30: Description | G30: Amount | H30: Amount
B31: Net Worth
D61: TOTAL VARIABLE | H61: =SUM(H31:H60)
D63: MONTHLY SUMMARY
D65: Total Income | E65: =E13
D66: Total Fixed Expenses | E66: =F26
D67: Total Variable Expenses | E67: =H61
D68: NET (Income - Expenses) | E68: =E13-F26-H61

Sheet October
B2: Budget Year 2026
B4: SETUP
B5: Instructions | D5: OCTOBER INCOME
B6: Easy Setup
D7: Source | E7: Amount | F7: Date Received
B8: DASHBOARDS | D8: Salary
B9: All-in-One Dashboard | D9: Side Hustle
B10: Annual Totals | D10: Freelance
D11: Investments
B12: MONTHLY | D12: Other
B13: January | D13: TOTAL INCOME | E13: =SUM(E8:E12)
B14: February
B15: March | D15: FIXED EXPENSES
B16: April
B17: May | D17: Category | E17: Budget | F17: Actual | G17: Difference
B18: June | G18: =E18-F18
B19: July | G19: =E19-F19
B20: August | G20: =E20-F20
B21: September | G21: =E21-F21
B22: October | G22: =E22-F22
B23: November | G23: =E23-F23
B24: December | G24: =E24-F24
G25: =E25-F25
B26: WEALTH | D26: TOTAL FIXED | E26: =SUM(E18:E25) | F26: =SUM(F18:F25) | G26: =E26-F26
B27: 50-30-20
B28: Expense Dist | D28: VARIABLE EXPENSES
B29: Sinking Funds
B30: Debt Calc | D30: Date | E30: Category | F30: Description | G30: Amount | H30: Amount
B31: Net Worth
D61: TOTAL VARIABLE | H61: =SUM(H31:H60)
D63: MONTHLY SUMMARY
D65: Total Income | E65: =E13
D66: Total Fixed Expenses | E66: =F26
D67: Total Variable Expenses | E67: =H61
D68: NET (Income - Expenses) | E68: =E13-F26-H61

Sheet November
B2: Budget Year 2026
B4: SETUP
B5: Instructions | D5: NOVEMBER INCOME
B6: Easy Setup
D7: Source | E7: Amount | F7: Date Received
B8: DASHBOARDS | D8: Salary
B9: All-in-One Dashboard | D9: Side Hustle
B10: Annual Totals | D10: Freelance
D11: Investments
B12: MONTHLY | D12: Other
B13: January | D13: TOTAL INCOME | E13: =SUM(E8:E12)
B14: February
B15: March | D15: FIXED EXPENSES
B16: April
B17: May | D17: Category | E17: Budget | F17: Actual | G17: Difference
B18: June | G18: =E18-F18
B19: July | G19: =E19-F19
B20: August | G20: =E20-F20
B21: September | G21: =E21-F21
B22: October | G22: =E22-F22
B23: November | G23: =E23-F23
B24: December | G24: =E24-F24
G25: =E25-F25
B26: WEALTH | D26: TOTAL FIXED | E26: =SUM(E18:E25) | F26: =SUM(F18:F25) | G26: =E26-F26
B27: 50-30-20
B28: Expense Dist | D28: VARIABLE EXPENSES
B29: Sinking Funds
B30: Debt Calc | D30: Date | E30: Category | F30: Description | G30: Amount | H30: Amount
B31: Net Worth
D61: TOTAL VARIABLE | H61: =SUM(H31:H60)
D63: MONTHLY SUMMARY
D65: Total Income | E65: =E13
D66: Total Fixed Expenses | E66: =F26
D67: Total Variable Expenses | E67: =H61
D68: NET (Income - Expenses) | E68: =E13-F26-H61

Sheet December
B2: Budget Year 2026
B4: SETUP
B5: Instructions | D5: DECEMBER INCOME
B6: Easy Setup
D7: Source | E7: Amount | F7: Date Received
B8: DASHBOARDS | D8: Salary
B9: All-in-One Dashboard | D9: Side Hustle
B10: Annual Totals | D10: Freelance
D11: Investments
B12: MONTHLY | D12: Other
B13: January | D13: TOTAL INCOME | E13: =SUM(E8:E12)
B14: February
B15: March | D15: FIXED EXPENSES
B16: April
B17: May | D17: Category | E17: Budget | F17: Actual | G17: Difference
B18: June | G18: =E18-F18
B19: July | G19: =E19-F19
B20: August | G20: =E20-F20
B21: September | G21: =E21-F21
B22: October | G22: =E22-F22
B23: November | G23: =E23-F23
B24: December | G24: =E24-F24
G25: =E25-F25
B26: WEALTH | D26: TOTAL FIXED | E26: =SUM(E18:E25) | F26: =SUM(F18:F25) | G26: =E26-F26
B27: 50-30-20
B28: Expense Dist | D28: VARIABLE EXPENSES
B29: Sinking Funds
B30: Debt Calc | D30: Date | E30: Category | F30: Description | G30: Amount | H30: Amount
B31: Net Worth
D61: TOTAL VARIABLE | H61: =SUM(H31:H60)
D63: MONTHLY SUMMARY
D65: Total Income | E65: =E13
D66: Total Fixed Expenses | E66: =F26
D67: Total Variable Expenses | E67: =H61
D68: NET (Income - Expenses) | E68: =E13-F26-H61

Sheet 50-30-20
AH1: Category | AI1: Target | AJ1: Actual
B2: Budget Year 2026 | AH2: Needs | AI2: 50 | AJ2: =G14*100
AH3: Wants | AI3: 30 | AJ3: =G15*100
B4: SETUP | AH4: Savings | AI4: 20 | AJ4: =G16*100
B5: Instructions | D5: 50 / 30 / 20 BUDGET RULE
B6: Easy Setup
D7: 50% NEEDS - Essential expenses you must pay (housing, utilities, groceries, transportation, insurance, healthcare)
B8: DASHBOARDS | D8: 30% WANTS - Non-essential spending that improves quality of life (entertainment, dining, shopping, subscriptions)
B9: All-in-One Dashboard | D9: 20% SAVINGS - Savings and debt repayment beyond minimums (savings, investments, extra debt payments)
B10: Annual Totals
D11: YOUR ACTUAL SPLIT
B12: MONTHLY
B13: January | D13: Category | E13: Target % | F13: Amount | G13: Actual %
B14: February | D14: Needs (50%) | E14: 0.5 | F14: =SUMPRODUCT((January!D18:D25="Housing")*(January!F18:F25))+SUMPRODUCT((January!D18:D25="Utilities")*(January!F18:F25))+SUMPRODUCT((January!D18:D25="Insurance")*(January!F18:F25))+SUMPRODUCT((January!D18:D25="Transportation")*(January!F18:F25))+SUMPRODUCT((January!D18:D25="Healthcare")*(January!F18:F25))+SUMPRODUCT((January!D18:D25="Groceries")*(January!F18:F25)) | G14: =IF(F17>0,F14/F17,0)
B15: March | D15: Wants (30%) | E15: 0.3 | F15: =SUMPRODUCT((January!D18:D25="Entertainment")*(January!F18:F25))+SUMPRODUCT((January!D18:D25="Dining Out")*(January!F18:F25))+SUMPRODUCT((January!D18:D25="Shopping")*(January!F18:F25))+SUMPRODUCT((January!D18:D25="Subscriptions")*(January!F18:F25))+SUMPRODUCT((January!D18:D25="Education")*(January!F18:F25))+SUMPRODUCT((January!D18:D25="Personal Care")*(January!F18:F25))+SUMPRODUCT((January!D18:D25="Gifts")*(January!F18:F25)) | G15: =IF(F17>0,F15/F17,0)
B16: April | D16: Savings (20%) | E16: 0.2 | F16: =SUMPRODUCT((January!D18:D25="Savings")*(January!F18:F25))+SUMPRODUCT((January!D18:D25="Debt Payments")*(January!F18:F25)) | G16: =IF(F17>0,F16/F17,0)
B17: May | D17: TOTAL | F17: =SUM(F14:F16) | G17: =SUM(G14:G16)
B18: June
B19: July
B20: August
B21: September
B22: October
B23: November
B24: December
B26: WEALTH
B27: 50-30-20
B28: Expense Dist
B29: Sinking Funds
B30: Debt Calc
B31: Net Worth

Sheet Expense Dist
B2: Budget Year 2026
B4: SETUP
B5: Instructions | D5: EXPENSE DISTRIBUTION
B6: Easy Setup
D7: Category | E7: Total Spent | F7: % of Total
B8: DASHBOARDS | D8: Housing | E8: ='Annual Totals'!Q8 | F8: =IF(SUM(E8:E23)>0,E8/SUM(E8:E23),0)
B9: All-in-One Dashboard | D9: Utilities | E9: ='Annual Totals'!Q9 | F9: =IF(SUM(E8:E23)>0,E9/SUM(E8:E23),0)
B10: Annual Totals | D10: Groceries | E10: ='Annual Totals'!Q10 | F10: =IF(SUM(E8:E23)>0,E10/SUM(E8:E23),0)
D11: Transportation | E11: ='Annual Totals'!Q11 | F11: =IF(SUM(E8:E23)>0,E11/SUM(E8:E23),0)
B12: MONTHLY | D12: Insurance | E12: ='Annual Totals'!Q12 | F12: =IF(SUM(E8:E23)>0,E12/SUM(E8:E23),0)
B13: January | D13: Healthcare | E13: ='Annual Totals'!Q13 | F13: =IF(SUM(E8:E23)>0,E13/SUM(E8:E23),0)
B14: February | D14: Entertainment | E14: ='Annual Totals'!Q14 | F14: =IF(SUM(E8:E23)>0,E14/SUM(E8:E23),0)
B15: March | D15: Dining Out | E15: ='Annual Totals'!Q15 | F15: =IF(SUM(E8:E23)>0,E15/SUM(E8:E23),0)
B16: April | D16: Shopping | E16: ='Annual Totals'!Q16 | F16: =IF(SUM(E8:E23)>0,E16/SUM(E8:E23),0)
B17: May | D17: Subscriptions | E17: ='Annual Totals'!Q17 | F17: =IF(SUM(E8:E23)>0,E17/SUM(E8:E23),0)
B18: June | D18: Savings | E18: ='Annual Totals'!Q18 | F18: =IF(SUM(E8:E23)>0,E18/SUM(E8:E23),0)
B19: July | D19: Debt Payments | E19: ='Annual Totals'!Q19 | F19: =IF(SUM(E8:E23)>0,E19/SUM(E8:E23),0)
B20: August | D20: Education | E20: ='Annual Totals'!Q20 | F20: =IF(SUM(E8:E23)>0,E20/SUM(E8:E23),0)
B21: September | D21: Personal Care | E21: ='Annual Totals'!Q21 | F21: =IF(SUM(E8:E23)>0,E21/SUM(E8:E23),0)
B22: October | D22: Gifts | E22: ='Annual Totals'!Q22 | F22: =IF(SUM(E8:E23)>0,E22/SUM(E8:E23),0)
B23: November | D23: Miscellaneous | E23: ='Annual Totals'!Q23 | F23: =IF(SUM(E8:E23)>0,E23/SUM(E8:E23),0)
B24: December | D24: TOTAL | E24: =SUM(E8:E23) | F24: 100%
B26: WEALTH
B27: 50-30-20
B28: Expense Dist
B29: Sinking Funds
B30: Debt Calc
B31: Net Worth

Sheet Sinking Funds
B2: Budget Year 2026
B4: SETUP
B5: Instructions | D5: SINKING FUNDS TRACKER
B6: Easy Setup
D7: Goal Name | E7: Target Amount | F7: Current Amount | G7: Monthly Contribution | H7: Progress % | I7: Months Left
B8: DASHBOARDS | D8: Emergency Fund | E8: 10000 | F8: 3500 | G8: 500 | H8: =IF(E8>0,F8/E8,0) | I8: =IF(G8>0,ROUNDUP((E8-F8)/G8,0),0)
B9: All-in-One Dashboard | D9: Vacation | E9: 3000 | F9: 1200 | G9: 300 | H9: =IF(E9>0,F9/E9,0) | I9: =IF(G9>0,ROUNDUP((E9-F9)/G9,0),0)
B10: Annual Totals | D10: Car Maintenance | E10: 1500 | F10: 400 | G10: 150 | H10: =IF(E10>0,F10/E10,0) | I10: =IF(G10>0,ROUNDUP((E10-F10)/G10,0),0)
D11: Holiday Gifts | E11: 1000 | F11: 200 | G11: 100 | H11: =IF(E11>0,F11/E11,0) | I11: =IF(G11>0,ROUNDUP((E11-F11)/G11,0),0)
B12: MONTHLY | D12: Home Repairs | E12: 5000 | F12: 800 | G12: 200 | H12: =IF(E12>0,F12/E12,0) | I12: =IF(G12>0,ROUNDUP((E12-F12)/G12,0),0)
B13: January | H13: =IF(E13>0,F13/E13,0) | I13: =IF(G13>0,ROUNDUP((E13-F13)/G13,0),0)
B14: February | H14: =IF(E14>0,F14/E14,0) | I14: =IF(G14>0,ROUNDUP((E14-F14)/G14,0),0)
B15: March | H15: =IF(E15>0,F15/E15,0) | I15: =IF(G15>0,ROUNDUP((E15-F15)/G15,0),0)
B16: April | H16: =IF(E16>0,F16/E16,0) | I16: =IF(G16>0,ROUNDUP((E16-F16)/G16,0),0)
B17: May | H17: =IF(E17>0,F17/E17,0) | I17: =IF(G17>0,ROUNDUP((E17-F17)/G17,0),0)
B18: June | D18: TOTALS | E18: =SUM(E8:E17) | F18: =SUM(F8:F17) | G18: =SUM(G8:G17) | H18: =IF(E18>0,F18/E18,0)
B19: July
B20: August
B21: September
B22: October
B23: November
B24: December
B26: WEALTH
B27: 50-30-20
B28: Expense Dist
B29: Sinking Funds
B30: Debt Calc
B31: Net Worth

Sheet Debt Calc
B2: Budget Year 2026
B4: SETUP
B5: Instructions | D5: DEBT PAYOFF CALCULATOR
B6: Easy Setup
D7: Debt Name | E7: Balance | F7: Interest Rate | G7: Min Payment | H7: Extra Payment | I7: Payoff Months | J7: Total Interest
B8: DASHBOARDS | D8: Credit Card 1 | E8: 5000 | F8: 0.199 | G8: 150 | H8: 50 | I8: =IF(AND(E8>0,(G8+H8)>(E8*F8/12)),ROUNDUP(E8/((G8+H8)-(E8*F8/12)),0),0) | J8: =IF(I8>0,(G8+H8)*I8-E8,0)
B9: All-in-One Dashboard | D9: Credit Card 2 | E9: 3000 | F9: 0.169 | G9: 90 | H9: 25 | I9: =IF(AND(E9>0,(G9+H9)>(E9*F9/12)),ROUNDUP(E9/((G9+H9)-(E9*F9/12)),0),0) | J9: =IF(I9>0,(G9+H9)*I9-E9,0)
B10: Annual Totals | D10: Student Loan | E10: 25000 | F10: 0.055 | G10: 280 | H10: 0 | I10: =IF(AND(E10>0,(G10+H10)>(E10*F10/12)),ROUNDUP(E10/((G10+H10)-(E10*F10/12)),0),0) | J10: =IF(I10>0,(G10+H10)*I10-E10,0)
D11: Auto Loan | E11: 15000 | F11: 0.049 | G11: 350 | H11: 0 | I11: =IF(AND(E11>0,(G11+H11)>(E11*F11/12)),ROUNDUP(E11/((G11+H11)-(E11*F11/12)),0),0) | J11: =IF(I11>0,(G11+H11)*I11-E11,0)
B12: MONTHLY | I12: =IF(AND(E12>0,(G12+H12)>(E12*F12/12)),ROUNDUP(E12/((G12+H12)-(E12*F12/12)),0),0) | J12: =IF(I12>0,(G12+H12)*I12-E12,0)
B13: January | I13: =IF(AND(E13>0,(G13+H13)>(E13*F13/12)),ROUNDUP(E13/((G13+H13)-(E13*F13/12)),0),0) | J13: =IF(I13>0,(G13+H13)*I13-E13,0)
B14: February | I14: =IF(AND(E14>0,(G14+H14)>(E14*F14/12)),ROUNDUP(E14/((G14+H14)-(E14*F14/12)),0),0) | J14: =IF(I14>0,(G14+H14)*I14-E14,0)
B15: March | I15: =IF(AND(E15>0,(G15+H15)>(E15*F15/12)),ROUNDUP(E15/((G15+H15)-(E15*F15/12)),0),0) | J15: =IF(I15>0,(G15+H15)*I15-E15,0)
B16: April | I16: =IF(AND(E16>0,(G16+H16)>(E16*F16/12)),ROUNDUP(E16/((G16+H16)-(E16*F16/12)),0),0) | J16: =IF(I16>0,(G16+H16)*I16-E16,0)
B17: May | I17: =IF(AND(E17>0,(G17+H17)>(E17*F17/12)),ROUNDUP(E17/((G17+H17)-(E17*F17/12)),0),0) | J17: =IF(I17>0,(G17+H17)*I17-E17,0)
B18: June | D18: TOTALS | E18: =SUM(E8:E17) | G18: =SUM(G8:G17) | H18: =SUM(H8:H17) | J18: =SUM(J8:J17)
B19: July
B20: August
B21: September
B22: October
B23: November
B24: December
B26: WEALTH
B27: 50-30-20
B28: Expense Dist
B29: Sinking Funds
B30: Debt Calc
B31: Net Worth

Sheet Net Worth
B2: Budget Year 2026
B4: SETUP
B5: Instructions | D5: NET WORTH TRACKER
B6: Easy Setup
D7: ASSETS
B8: DASHBOARDS | D8: Asset | E8: Value
B9: All-in-One Dashboard | D9: Checking Account | E9: 5000
B10: Annual Totals | D10: Savings Account | E10: 15000
D11: Investments (401k/IRA) | E11: 45000
B12: MONTHLY | D12: Property | E12: 250000
B13: January | D13: Vehicles | E13: 18000
B14: February | D14: Other Assets | E14: 2000
B15: March | D15: TOTAL ASSETS | E15: =SUM(E9:E14)
B16: April
B17: May | D17: LIABILITIES
B18: June | D18: Liability | E18: Balance
B19: July | D19: Mortgage | E19: 200000
B20: August | D20: Student Loans | E20: 25000
B21: September | D21: Credit Cards | E21: 8000
B22: October | D22: Auto Loan | E22: 15000
B23: November | D23: Other Liabilities | E23: 0
B24: December | D24: TOTAL LIABILITIES | E24: =SUM(E19:E23)
B26: WEALTH | D26: NET WORTH
B27: 50-30-20 | D27: =E15-E24
B28: Expense Dist
B29: Sinking Funds
B30: Debt Calc
B31: Net Worth
