Workbook

Sheet Instructions
B2: =IF(SETUP!G6="","SET DATE",IF(SETUP!G6-TODAY()<0,"PAST DUE",SETUP!G6-TODAY()&" DAYS")) | D2: HOW TO USE YOUR WEDDING PLANNER
B4: OVERVIEW | D4: GETTING STARTED
B5: Instructions | D5: Start with the SETUP tab — enter your names, wedding date, and total budget.
B6: SETUP | D6: All other tabs auto-populate key details (countdown, currency) from SETUP.
B7: DASHBOARD | D7: Navigate between tabs using the sidebar links on the left of every page.
B9: PLANNING | D9: ENTERING YOUR DATA
B10: Save the Date | D10: Sample data is pre-filled in the first 3-5 rows of each tab as examples.
B11: Theme | D11: Replace the sample data with your own information.
B12: Calendar | D12: Use dropdown menus wherever you see them — they keep data consistent.
B13: Timeline | D13: Formulas update automatically as you enter data.
B15: DAY OF | D15: DASHBOARD & CHARTS
B16: Itinerary | D16: The DASHBOARD tab gives you a visual overview of your entire wedding plan.
B17: Packing List | D17: Charts auto-update as you enter data in each tab.
D18: Additional charts appear on Budget, Guest List, Timeline, and other tabs.
B19: VENDORS & VENUE | D19: Each chart has a header explaining exactly what it tracks.
B20: Vendors
B21: Venues | D21: CUSTOMIZATION
B22: Contacts | D22: Change colors: Home > Cell Styles or modify fill colors.
D23: Add more rows: insert rows ABOVE the total/summary row.
B24: FINANCES | D24: Add tabs: right-click any tab > Insert > copy structure from existing.
B25: BUDGET
B26: Honeymoon | D26: TIPS FOR BEST RESULTS
D27: Fill in the Budget tab early — the Dashboard tracks spending automatically.
B28: GUESTS | D28: Update the Timeline tab weekly to keep your planning on track.
B29: Guest List | D29: Use the Guest List tab consistently — it feeds the Seating Plan and Food tabs.
B30: Seating Plan | D30: The Vendors tab helps you compare quotes side by side before booking.
B31: Wedding Party
B33: DETAILS
B34: Food & Drinks
B35: Music
B36: Photoshoot
B37: Photo Gallery
B39: GIFTS
B40: Gifts & Thanks

Sheet SETUP
B2: =IF(SETUP!G6="","SET DATE",IF(SETUP!G6-TODAY()<0,"PAST DUE",SETUP!G6-TODAY()&" DAYS")) | D2: SETUP
B4: OVERVIEW | D4: WEDDING DETAILS
B5: Instructions | D5: Partner 1 Name | G5: Sarah
B6: SETUP | D6: Wedding Date | G6: 2025-09-15
B7: DASHBOARD | D7: Partner 2 Name | G7: Michael
D8: Venue Name | G8: Rosewood Gardens
B9: PLANNING | D9: Total Budget | G9: 45000
B10: Save the Date | D10: Currency | G10: USD
B11: Theme | D11: Estimated Guests | G11: 150
B12: Calendar | D12: Wedding Style | G12: Rustic Elegant
B13: Timeline | D13: Color Theme | G13: Sage & Dusty Rose
B15: DAY OF
B16: Itinerary
B17: Packing List
B19: VENDORS & VENUE
B20: Vendors
B21: Venues
B22: Contacts
B24: FINANCES
B25: BUDGET
B26: Honeymoon
B28: GUESTS
B29: Guest List
... B40: Gifts & Thanks

Sheet Save the Date
B2: =IF(SETUP!G6="","SET DATE",IF(SETUP!G6-TODAY()<0,"PAST DUE",SETUP!G6-TODAY()&" DAYS")) | D2: SAVE THE DATE
B4: OVERVIEW | D4: KEY DATES & ANNOUNCEMENTS
B5: Instructions | D5: Milestone | E5: Target Date | F5: Actual Date | G5: Status | H5: Notes
B6: SETUP | D6: Engagement Announcement | E6: 2025-01-01 | F6: 2025-01-01 | G6: Complete | H6: Social media + family
B7: DASHBOARD | D7: Save the Dates Sent | E7: 2025-03-01 | F7: 2025-03-05 | G7: Complete | H7: Mailed 150
D8: Invitations Sent | E8: 2025-06-01 | G8: In Progress | H8: Design approved
B9: PLANNING | D9: RSVP Deadline | E9: 2025-08-01 | G9: Not Started | H9: 6 weeks before
B10: Save the Date | D10: Final Guest Count | E10: 2025-08-15 | G10: Not Started | H10: Confirm with caterer
B11: Theme
B12: Calendar
B13: Timeline
B15: DAY OF
B16: Itinerary
B17: Packing List
B19: VENDORS & VENUE
B20: Vendors
B21: Venues
B22: Contacts
B24: FINANCES
B25: BUDGET
... B40: Gifts & Thanks

Sheet Theme
B2: =IF(SETUP!G6="","SET DATE",IF(SETUP!G6-TODAY()<0,"PAST DUE",SETUP!G6-TODAY()&" DAYS")) | D2: WEDDING THEME & STYLE
B4: OVERVIEW | D4: THEME DETAILS
B5: Instructions | D5: Overall Style | G5: =SETUP!G12
B6: SETUP | D6: Color Palette | G6: =SETUP!G13
B7: DASHBOARD | D7: Season | G7: Fall
D8: Mood / Vibe | G8: Romantic, warm, natural
B9: PLANNING | D9: Inspiration Sources | G9: Pinterest board, bridal magazines
B10: Save the Date
B11: Theme | D11: DECOR & DETAILS
B12: Calendar | D12: Category | E12: Description | F12: Vendor | G12: Budget | H12: Status
B13: Timeline | D13: Centerpieces | E13: Mixed greenery + candles | F13: Bloom & Wild | G13: 800 | H13: Booked
D14: Lighting | E14: String lights + lanterns | F14: EventGlow Co | G14: 600 | H14: In Progress
B15: DAY OF | D15: Linens | E15: Ivory tablecloths, sage runners | F15: Linen Library | G15: 400 | H15: Not Started
B16: Itinerary | D16: Signage | E16: Acrylic welcome sign + table numbers | F16: Etsy shop | G16: 200 | H16: Not Started
B17: Packing List
B19: VENDORS & VENUE
B20: Vendors
B21: Venues
B22: Contacts
B24: FINANCES
B25: BUDGET
B26: Honeymoon
B28: GUESTS
B29: Guest List
B30: Seating Plan
B31: Wedding Party
... B40: Gifts & Thanks

Sheet DASHBOARD
B2: =IF(SETUP!G6="","SET DATE",IF(SETUP!G6-TODAY()<0,"PAST DUE",SETUP!G6-TODAY()&" DAYS")) | D2: ALL-IN-ONE DASHBOARD
B4: OVERVIEW
B5: Instructions | D5: =SETUP!G9 | H5: =SUM(BUDGET!H6:H30) | L5: =COUNTIF('Guest List'!H6:H200,"Attending") | P5: =COUNTIF(Timeline!G6:G100,"Complete")
B6: SETUP | D6: TOTAL BUDGET | H6: TOTAL SPENT | L6: GUESTS ATTENDING | P6: TASKS COMPLETE
B7: DASHBOARD
D8: BUDGET ALLOCATION BY CATEGORY | L8: GUEST RSVP STATUS
B9: PLANNING | D9: Shows how your total wedding budget is distributed across all spending categories | L9: Current response breakdown across all invited guests — updates as you log RSVPs
B10: Save the Date
B11: Theme
B12: Calendar
B13: Timeline
B15: DAY OF
B16: Itinerary
B17: Packing List
B19: VENDORS & VENUE
B20: Vendors
B21: Venues
B22: Contacts
B24: FINANCES
... B26: Honeymoon
B28: GUESTS | D28: CUMULATIVE SPENDING OVER TIME | L28: PLANNING TASK PROGRESS
B29: Guest List | D29: Tracks your total spending month by month so you can see if you are on pace with your budget | L29: Shows how many of your wedding tasks are complete, in progress, or not yet started
B30: Seating Plan
B31: Wedding Party
B33: DETAILS
B34: Food & Drinks
B35: Music
B36: Photoshoot
B37: Photo Gallery
B39: GIFTS
B40: Gifts & Thanks
D48: BUDGET VS ACTUAL SPENDING | L48: GUEST MEAL PREFERENCES
D49: Compare your planned budget against real spending for each category — spot overages instantly | L49: Breakdown of meal selections across all attending guests — share with your caterer
D69: Category | E69: Spent | G69: RSVP Status | H69: Count | J69: Month | K69: Cumulative Spent | M69: Status | N69: Count
D70: Venue & Rentals | E70: =SUMIF(BUDGET!D6:D30,D70,BUDGET!H6:H30) | G70: Attending | H70: =COUNTIF('Guest List'!H6:H200,"Attending") | J70: Jan | K70: 2000 | M70: Complete | N70: =COUNTIF(Timeline!G6:G100,"Complete")
D71: Catering | E71: =SUMIF(BUDGET!D6:D30,D71,BUDGET!H6:H30) | G71: Pending | H71: =COUNTIF('Guest List'!H6:H200,"Pending") | J71: Feb | K71: 5500 | M71: In Progress | N71: =COUNTIF(Timeline!G6:G100,"In Progress")
D72: Photography | E72: =SUMIF(BUDGET!D6:D30,D72,BUDGET!H6:H30) | G72: Declined | H72: =COUNTIF('Guest List'!H6:H200,"Declined") | J72: Mar | K72: 8000 | M72: Not Started | N72: =COUNTIF(Timeline!G6:G100,"Not Started")
D73: Florals & Decor | E73: =SUMIF(BUDGET!D6:D30,D73,BUDGET!H6:H30) | G73: No Response | H73: =COUNTIF('Guest List'!H6:H200,"No Response") | J73: Apr | K73: 12000
D74: Music & Entertainment | E74: =SUMIF(BUDGET!D6:D30,D74,BUDGET!H6:H30) | J74: May | K74: 16000
D75: Wedding Attire | E75: =SUMIF(BUDGET!D6:D30,D75,BUDGET!H6:H30) | J75: Jun | K75: 22000
...

Sheet Calendar
B2: =IF(SETUP!G6="","SET DATE",IF(SETUP!G6-TODAY()<0,"PAST DUE",SETUP!G6-TODAY()&" DAYS")) | D2: WEDDING CALENDAR
B4: OVERVIEW | D4: KEY DATES OVERVIEW
B5: Instructions | D5: Date | E5: Event / Deadline | F5: Category | G5: Priority | H5: Notes
B6: SETUP | D6: 2025-01-15 | E6: Book venue | F6: Venue | G6: High | H6: Confirmed Rosewood
B7: DASHBOARD | D7: 2025-03-01 | E7: Send save the dates | F7: Stationery | G7: High | H7: Mailed
D8: 2025-04-01 | E8: Book photographer | F8: Photography | G8: High | H8: Shortlisted 3
B9: PLANNING | D9: 2025-05-15 | E9: Order invitations | F9: Stationery | G9: Medium
B10: Save the Date | D10: 2025-06-01 | E10: Cake tasting | F10: Catering | G10: Medium | H10: 3 bakeries
B11: Theme | D11: 2025-06-15 | E11: Book florist | F11: Florals | G11: Medium
B12: Calendar | D12: 2025-07-01 | E12: Final menu selection | F12: Catering | G12: High
B13: Timeline | D13: 2025-08-01 | E13: RSVP deadline | F13: Guests | G13: High
D14: 2025-08-15 | E14: Final guest count | F14: Guests | G14: High | H14: Notify caterer
B15: DAY OF | D15: 2025-09-01 | E15: Final fittings | F15: Attire | G15: High
B16: Itinerary
B17: Packing List
B19: VENDORS & VENUE
B20: Vendors
B21: Venues
B22: Contacts
B24: FINANCES
B25: BUDGET
B26: Honeymoon
B28: GUESTS
B29: Guest List
B30: Seating Plan
... B40: Gifts & Thanks

Sheet Timeline
B2: =IF(SETUP!G6="","SET DATE",IF(SETUP!G6-TODAY()<0,"PAST DUE",SETUP!G6-TODAY()&" DAYS")) | D2: PLANNING TIMELINE
B4: OVERVIEW | D4: TASK TRACKER
B5: Instructions | D5: Task | E5: Category | F5: Due Date | G5: Status | H5: Priority | I5: Assigned To | J5: Notes
B6: SETUP | D6: Book venue | E6: Venue | F6: 2025-01-15 | G6: Complete | H6: High | I6: Both | J6: Rosewood confirmed
B7: DASHBOARD | D7: Send save the dates | E7: Stationery | F7: 2025-03-01 | G7: Complete | H7: High | I7: Sarah | J7: Mailed 150
D8: Book photographer | E8: Photography | F8: 2025-04-01 | G8: In Progress | H8: High | I8: Michael | J8: Shortlisted 3
B9: PLANNING | D9: Order invitations | E9: Stationery | F9: 2025-05-15 | G9: Not Started | H9: Medium | I9: Sarah | J9: Design approved
B10: Save the Date | D10: Cake tasting | E10: Catering | F10: 2025-06-01 | G10: Not Started | H10: Medium | I10: Both | J10: 3 bakeries
B11: Theme | D11: Book DJ / Band | E11: Entertainment | F11: 2025-04-15 | G11: Complete | H11: High | I11: Michael | J11: DJ Smooth booked
B12: Calendar | D12: Choose bridesmaid dresses | E12: Attire | F12: 2025-05-01 | G12: In Progress | H12: Medium | I12: Sarah
B13: Timeline | D13: Book transportation | E13: Transport | F13: 2025-07-01 | G13: Not Started | H13: Low | I13: Michael
D14: Plan rehearsal dinner | E14: Events | F14: 2025-08-01 | G14: Not Started | H14: Medium | I14: Both
B15: DAY OF | D15: Write vows | E15: Ceremony | F15: 2025-08-15 | G15: Not Started | H15: High | I15: Both
B16: Itinerary
B17: Packing List
D18: TASK ANALYTICS
B19: VENDORS & VENUE | D19: Status | E19: Count | G19: Priority | H19: Count
B20: Vendors | D20: Complete | E20: =COUNTIF(G6:G16,"Complete") | G20: High | H20: =COUNTIF(H6:H16,"High")
B21: Venues | D21: In Progress | E21: =COUNTIF(G6:G16,"In Progress") | G21: Medium | H21: =COUNTIF(H6:H16,"Medium")
B22: Contacts | D22: Not Started | E22: =COUNTIF(G6:G16,"Not Started") | G22: Low | H22: =COUNTIF(H6:H16,"Low")
B24: FINANCES | D24: TASK COMPLETION STATUS | L24: TASK PRIORITY DISTRIBUTION
B25: BUDGET | D25: Visual breakdown of how many planning tasks are done, underway, or waiting to start | L25: Balance of high, medium, and low priority tasks — ensure critical items get attention first
B26: Honeymoon
B28: GUESTS
B29: Guest List
B30: Seating Plan
B31: Wedding Party
B33: DETAILS
B34: Food & Drinks
B35: Music
B36: Photoshoot
B37: Photo Gallery
B39: GIFTS
B40: Gifts & Thanks

Sheet Itinerary
B2: =IF(SETUP!G6="","SET DATE",IF(SETUP!G6-TODAY()<0,"PAST DUE",SETUP!G6-TODAY()&" DAYS")) | D2: WEDDING DAY ITINERARY
B4: OVERVIEW | D4: DAY-OF SCHEDULE
B5: Instructions | D5: Time | E5: Event | F5: Location | G5: Who | H5: Duration | I5: Notes
B6: SETUP | D6: 7:00 AM | E6: Hair & Makeup begins | F6: Bridal Suite | G6: Bride + Bridesmaids | H6: 3 hrs | I6: Coffee & pastries
B7: DASHBOARD | D7: 10:00 AM | E7: Groom prep | F7: Groom Suite | G7: Groom + Groomsmen | H7: 1.5 hrs
D8: 11:30 AM | E8: First look photos | F8: Garden | G8: Couple + Photographer | H8: 45 min
B9: PLANNING | D9: 12:30 PM | E9: Wedding party photos | F9: Garden + Venue | G9: Full party | H9: 1 hr
B10: Save the Date | D10: 2:00 PM | E10: Guests arrive | F10: Ceremony area | G10: All guests | H10: 30 min | I10: Ushers seat guests
B11: Theme | D11: 2:30 PM | E11: Ceremony begins | F11: Garden Pavilion | G11: Everyone | H11: 30 min
B12: Calendar | D12: 3:00 PM | E12: Cocktail hour | F12: Terrace | G12: Guests | H12: 1 hr | I12: Passed apps + bar
B13: Timeline | D13: 4:00 PM | E13: Reception begins | F13: Ballroom | G13: Everyone | H13: 5 hrs
D14: 4:30 PM | E14: First dance | F14: Dance floor | G14: Couple | H14: 5 min | I14: Song: TBD
B15: DAY OF | D15: 9:00 PM | E15: Sparkler send-off | F15: Front entrance | G15: Everyone | H15: 15 min
B16: Itinerary
B17: Packing List
B19: VENDORS & VENUE
B20: Vendors
B21: Venues
B22: Contacts
B24: FINANCES
B25: BUDGET
B26: Honeymoon
B28: GUESTS
B29: Guest List
B30: Seating Plan
... B40: Gifts & Thanks

Sheet Packing List
B2: =IF(SETUP!G6="","SET DATE",IF(SETUP!G6-TODAY()<0,"PAST DUE",SETUP!G6-TODAY()&" DAYS")) | D2: WEDDING DAY PACKING LIST
B4: OVERVIEW | D4: ITEMS TO BRING
B5: Instructions | D5: Item | E5: Category | F5: Packed | G5: Quantity | H5: Notes
B6: SETUP | D6: Wedding dress | E6: Attire | F6: Yes | G6: 1 | H6: Steamed night before
B7: DASHBOARD | D7: Veil / Headpiece | E7: Attire | F7: Yes | G7: 1
D8: Wedding rings | E8: Ceremony | F8: No | G8: 2 | H8: Best man has them
B9: PLANNING | D9: Vows (printed) | E9: Ceremony | F9: No | G9: 2 | H9: Backup copies
B10: Save the Date | D10: Emergency kit | E10: Supplies | F10: Yes | G10: 1 | H10: Sewing kit, stain remover, pain reliever
B11: Theme | D11: Marriage license | E11: Legal | F11: No | G11: 1 | H11: CRITICAL — do not forget
B12: Calendar | D12: Card box | E12: Reception | F12: No | G12: 1 | H12: For gift cards
B13: Timeline | D13: Guest book + pen | E13: Reception | F13: No | G13: 1
D14: Phone charger | E14: Personal | F14: No | G14: 2 | H14: One for each partner
B15: DAY OF | D15: Change of shoes | E15: Attire | F15: No | G15: 1 | H15: Comfy for dancing
B16: Itinerary
B17: Packing List
B19: VENDORS & VENUE
B20: Vendors
B21: Venues
B22: Contacts
B24: FINANCES
B25: BUDGET
B26: Honeymoon
B28: GUESTS
B29: Guest List
B30: Seating Plan
... B40: Gifts & Thanks

Sheet Vendors
B2: =IF(SETUP!G6="","SET DATE",IF(SETUP!G6-TODAY()<0,"PAST DUE",SETUP!G6-TODAY()&" DAYS")) | D2: VENDOR TRACKER
B4: OVERVIEW | D4: BOOKED & PROSPECTIVE VENDORS
B5: Instructions | D5: Vendor Name | E5: Category | F5: Contact | G5: Phone | H5: Email | I5: Quote | J5: Status | K5: Rating | L5: Notes
B6: SETUP | D6: Rosewood Gardens | E6: Venue | F6: Tom Hardy | G6: 555-1001 | H6: tom@rosewood.com | I6: 14500 | J6: Booked | K6: 5 | L6: Perfect garden
B7: DASHBOARD | D7: Bella Cucina | E7: Catering | F7: Chef Marco | G7: 555-1002 | H7: marco@bella.com | I7: 7200 | J7: Booked | K7: 4 | L7: Italian menu
D8: Lens & Light Studio | E8: Photography | F8: Amy Park | G8: 555-1003 | H8: amy@lens.com | I8: 3800 | J8: Pending | K8: 5 | L8: Portfolio loved
B9: PLANNING | D9: Bloom & Wild | E9: Florals | F9: Nina Rose | G9: 555-1004 | H9: nina@bloom.com | I9: 2200 | J9: Booked | K9: 4 | L9: Rustic style
B10: Save the Date | D10: DJ Smooth | E10: Entertainment | F10: Dave King | G10: 555-1005 | H10: dave@dj.com | I10: 1500 | J10: Booked | K10: 4 | L10: Great reviews
B11: Theme
B12: Calendar
B13: Timeline | D13: VENDOR COST ANALYSIS
D14: VENDOR COST COMPARISON
B15: DAY OF | D15: Side-by-side comparison of quoted costs for each booked or prospective vendor
B16: Itinerary
B17: Packing List
B19: VENDORS & VENUE
B20: Vendors
B21: Venues
B22: Contacts
B24: FINANCES
B25: BUDGET
B26: Honeymoon
B28: GUESTS
B29: Guest List
B30: Seating Plan
... B40: Gifts & Thanks

Sheet Venues
B2: =IF(SETUP!G6="","SET DATE",IF(SETUP!G6-TODAY()<0,"PAST DUE",SETUP!G6-TODAY()&" DAYS")) | D2: VENUE COMPARISON
B4: OVERVIEW | D4: VENUE OPTIONS
B5: Instructions | D5: Venue Name | E5: Location | F5: Capacity | G5: Cost | H5: Availability | I5: Pros | J5: Cons | K5: Rating
B6: SETUP | D6: Rosewood Gardens | E6: Hillside, CA | F6: 200 | G6: 14500 | H6: Sep 15 available | I6: Beautiful gardens | J6: Far from city | K6: 5
B7: DASHBOARD | D7: The Grand Hall | E7: Downtown, CA | F7: 300 | G7: 18000 | H7: Sep 15 available | I7: Elegant, central | J7: Expensive | K7: 4
D8: Lakeside Lodge | E8: Lake View, CA | F8: 150 | G8: 11000 | H8: Sep booked | I8: Stunning views | J8: Weather risk | K8: 4
B9: PLANNING | D9: The Barn at Willow | E9: Rural, CA | F9: 120 | G9: 8500 | H9: Sep 15 available | I9: Rustic charm | J9: Limited parking | K9: 3
B10: Save the Date
B11: Theme
B12: Calendar
B13: Timeline
B15: DAY OF
B16: Itinerary
B17: Packing List
B19: VENDORS & VENUE
B20: Vendors
B21: Venues
B22: Contacts
B24: FINANCES
... B40: Gifts & Thanks

Sheet BUDGET
B2: =IF(SETUP!G6="","SET DATE",IF(SETUP!G6-TODAY()<0,"PAST DUE",SETUP!G6-TODAY()&" DAYS")) | D2: WEDDING BUDGET TRACKER
B4: OVERVIEW | D4: BUDGET BREAKDOWN
B5: Instructions | D5: Category | E5: Item | F5: Vendor | G5: Estimated | H5: Actual | I5: Paid | J5: Remaining | K5: Status | L5: Notes
B6: SETUP | D6: Venue & Rentals | E6: Venue fee | F6: Rosewood Gardens | G6: 15000 | H6: 14500 | I6: 14500 | J6: =H6-I6 | K6: Paid | L6: Full payment
B7: DASHBOARD | D7: Catering | E7: Full service | F7: Bella Cucina | G7: 8000 | H7: 7200 | I7: 3600 | J7: =H7-I7 | K7: Deposit | L7: 50% deposit
D8: Photography | E8: Full day + album | F8: Lens & Light | G8: 3500 | H8: 3800 | I8: 1900 | J8: =H8-I8 | K8: Deposit | L8: Over budget
B9: PLANNING | D9: Florals & Decor | E9: Centerpieces + arch | F9: Bloom & Wild | G9: 2500 | H9: 2200 | I9: 1100 | J9: =H9-I9 | K9: Deposit | L9: On track
B10: Save the Date | D10: Music & Entertainment | E10: DJ full night | F10: DJ Smooth | G10: 1500 | H10: 1500 | I10: 750 | J10: =H10-I10 | K10: Deposit
B11: Theme | D11: Wedding Attire | E11: Dress + suit + alterations | F11: Various | G11: 3000 | H11: 2700 | I11: 2700 | J11: =H11-I11 | K11: Paid | L11: Complete
B12: Calendar | D12: Stationery | E12: Invites + STDs + programs | F12: Etsy + Minted | G12: 500 | H12: 450 | I12: 450 | J12: =H12-I12 | K12: Paid
B13: Timeline | D13: Transportation | E13: Limo + shuttle | F13: TBD | G13: 1000 | H13: 900 | I13: 0 | J13: =H13-I13 | K13: Not Booked
D14: Cake & Desserts | E14: Wedding cake + dessert bar | F14: Sweet Layers | G14: 800 | H14: 750 | I14: 375 | J14: =H14-I14 | K14: Deposit
B15: DAY OF | D15: Favors & Gifts | E15: Guest favors + party gifts | F15: TBD | G15: 700 | H15: 600 | I15: 0 | J15: =H15-I15 | K15: Not Started
B16: Itinerary | D16: TOTALS | G16: =SUM(G6:G15) | H16: =SUM(H6:H15) | I16: =SUM(I6:I15) | J16: =SUM(J6:J15)
B17: Packing List
D18: BUDGET ANALYTICS
B19: VENDORS & VENUE | D19: Category | E19: Actual | G19: Month | H19: Cumulative
B20: Vendors | D20: =D6 | E20: =H6 | G20: Jan | H20: 2000
B21: Venues | D21: =D7 | E21: =H7 | G21: Feb | H21: 5500
B22: Contacts | D22: =D8 | E22: =H8 | G22: Mar | H22: 8000
D23: =D9 | E23: =H9 | G23: Apr | H23: 12000
B24: FINANCES | D24: =D10 | E24: =H10 | G24: May | H24: 16000
B25: BUDGET | D25: =D11 | E25: =H11 | G25: Jun | H25: 22000
B26: Honeymoon | D26: =D12 | E26: =H12 | G26: Jul | H26: 28000
D27: =D13 | E27: =H13 | G27: Aug | H27: 33000
B28: GUESTS | D28: =D14 | E28: =H14 | G28: Sep | H28: 38000
B29: Guest List | D29: =D15 | E29: =H15 | G29: Oct | H29: 41000
B30: Seating Plan | G30: Nov | H30: 43000
B31: Wedding Party | G31: Dec | H31: 45000
B33: DETAILS | D33: SPENDING DISTRIBUTION BY CATEGORY | L33: CUMULATIVE SPENDING TREND
B34: Food & Drinks | D34: Where your money is going — see which categories consume the largest share of your budget | L34: Track total spending month-by-month against your overall budget limit to stay on pace
B35: Music
B36: Photoshoot
B37: Photo Gallery
B39: GIFTS
B40: Gifts & Thanks

Sheet Contacts
B2: =IF(SETUP!G6="","SET DATE",IF(SETUP!G6-TODAY()<0,"PAST DUE",SETUP!G6-TODAY()&" DAYS")) | D2: CONTACT DIRECTORY
B4: OVERVIEW | D4: VENDOR & KEY CONTACTS
B5: Instructions | D5: Name | E5: Role / Company | F5: Phone | G5: Email | H5: Address | I5: Notes
B6: SETUP | D6: Tom Hardy | E6: Rosewood Gardens (Venue) | F6: 555-1001 | G6: tom@rosewood.com | H6: 123 Hill Rd | I6: Event coordinator
B7: DASHBOARD | D7: Chef Marco | E7: Bella Cucina (Catering) | F7: 555-1002 | G7: marco@bella.com | H7: 456 Main St
D8: Amy Park | E8: Lens & Light (Photo) | F8: 555-1003 | G8: amy@lens.com | I8: Lead photographer
B9: PLANNING | D9: Nina Rose | E9: Bloom & Wild (Florals) | F9: 555-1004 | G9: nina@bloom.com | H9: 789 Flower Ln
B10: Save the Date | D10: Dave King | E10: DJ Smooth (Entertainment) | F10: 555-1005 | G10: dave@dj.com | I10: Setup at 2pm
B11: Theme
B12: Calendar
B13: Timeline
B15: DAY OF
B16: Itinerary
B17: Packing List
B19: VENDORS & VENUE
B20: Vendors
B21: Venues
B22: Contacts
B24: FINANCES
B25: BUDGET
... B40: Gifts & Thanks

Sheet Guest List
B2: =IF(SETUP!G6="","SET DATE",IF(SETUP!G6-TODAY()<0,"PAST DUE",SETUP!G6-TODAY()&" DAYS")) | D2: GUEST LIST
B4: OVERVIEW | D4: GUEST TRACKER
B5: Instructions | D5: Guest Name | E5: Email | F5: Phone | G5: Party | H5: RSVP Status | I5: Meal Choice | J5: Table # | K5: Plus One | L5: Invite Sent | M5: Notes
B6: SETUP | D6: Emma Johnson | E6: emma@email.com | F6: 555-0101 | G6: Bride | H6: Attending | I6: Chicken | J6: 1 | K6: Yes | L6: Yes | M6: College friend
B7: DASHBOARD | D7: James Wilson | E7: james@email.com | F7: 555-0102 | G7: Groom | H7: Attending | I7: Beef | J7: 1 | K7: No | L7: Yes | M7: Best man
D8: Sophie Chen | E8: sophie@email.com | F8: 555-0103 | G8: Bride | H8: Pending | I8: Vegetarian | J8: 2 | K8: Yes | L8: Yes | M8: Cousin
B9: PLANNING | D9: Robert Taylor | E9: rob@email.com | F9: 555-0104 | G9: Groom | H9: Declined | K9: No | L9: Yes | M9: Work colleague
B10: Save the Date | D10: Maria Garcia | E10: maria@email.com | F10: 555-0105 | G10: Bride | H10: Attending | I10: Fish | J10: 2 | K10: Yes | L10: Yes | M10: Sister
B11: Theme
B12: Calendar | D12: TOTAL INVITED | E12: =COUNTA(D6:D200)
B13: Timeline
D14: GUEST ANALYTICS
B15: DAY OF | D15: RSVP Status | E15: Count | G15: Meal Choice | H15: Count | J15: Party | K15: Count
B16: Itinerary | D16: Attending | E16: =COUNTIF(H6:H200,"Attending") | G16: Chicken | H16: =COUNTIF(I6:I200,"Chicken") | J16: Bride | K16: =COUNTIF(G6:G200,"Bride")
B17: Packing List | D17: Pending | E17: =COUNTIF(H6:H200,"Pending") | G17: Beef | H17: =COUNTIF(I6:I200,"Beef") | J17: Groom | K17: =COUNTIF(G6:G200,"Groom")
D18: Declined | E18: =COUNTIF(H6:H200,"Declined") | G18: Fish | H18: =COUNTIF(I6:I200,"Fish")
B19: VENDORS & VENUE | D19: No Response | E19: =COUNTIF(H6:H200,"No Response") | G19: Vegetarian | H19: =COUNTIF(I6:I200,"Vegetarian")
B20: Vendors | G20: Vegan | H20: =COUNTIF(I6:I200,"Vegan")
B21: Venues
B22: Contacts | D22: RSVP RESPONSE BREAKDOWN | L22: MEAL SELECTION DISTRIBUTION
D23: Visual breakdown of guest responses — see at a glance how many have confirmed, are pending, or declined | L23: Guest meal preferences for catering coordination — share these totals directly with your caterer
B24: FINANCES
B25: BUDGET
B26: Honeymoon
B28: GUESTS
B29: Guest List
B30: Seating Plan
B31: Wedding Party
B33: DETAILS
B34: Food & Drinks
B35: Music
B36: Photoshoot
B37: Photo Gallery
... B40: Gifts & Thanks
D42: GUESTS BY PARTY SIDE
D43: See the balance of guests from the bride's side vs groom's side for seating and planning

Sheet Seating Plan
B2: =IF(SETUP!G6="","SET DATE",IF(SETUP!G6-TODAY()<0,"PAST DUE",SETUP!G6-TODAY()&" DAYS")) | D2: SEATING PLAN
B4: OVERVIEW | D4: TABLE ASSIGNMENTS
B5: Instructions | D5: Table # | E5: Guest 1 | F5: Guest 2 | G5: Guest 3 | H5: Guest 4 | I5: Guest 5 | J5: Guest 6 | K5: Guest 7 | L5: Guest 8 | M5: Seats Used
B6: SETUP | D6: 1 | E6: Emma Johnson | F6: James Wilson | G6: Maria Garcia | H6: +1 Emma | I6: +1 Maria | M6: =COUNTA(E6:K6)
B7: DASHBOARD | D7: 2 | E7: Sophie Chen | F7: +1 Sophie | M7: =COUNTA(E7:K7)
D8: 3 | M8: =COUNTA(E8:K8)
B9: PLANNING | D9: 4 | M9: =COUNTA(E9:K9)
B10: Save the Date | D10: 5 | M10: =COUNTA(E10:K10)
B11: Theme
B12: Calendar
B13: Timeline
B15: DAY OF
B16: Itinerary
B17: Packing List
B19: VENDORS & VENUE
B20: Vendors
B21: Venues
B22: Contacts
B24: FINANCES
B25: BUDGET
... B40: Gifts & Thanks

Sheet Wedding Party
B2: =IF(SETUP!G6="","SET DATE",IF(SETUP!G6-TODAY()<0,"PAST DUE",SETUP!G6-TODAY()&" DAYS")) | D2: WEDDING PARTY
B4: OVERVIEW | D4: BRIDAL PARTY & GROOMSMEN
B5: Instructions | D5: Name | E5: Role | F5: Side | G5: Phone | H5: Email | I5: Outfit Status | J5: Gift | K5: Notes
B6: SETUP | D6: James Wilson | E6: Best Man | F6: Groom | G6: 555-0102 | H6: james@email.com | I6: Fitted | J6: Watch | K6: Giving speech
B7: DASHBOARD | D7: Lisa Park | E7: Maid of Honor | F7: Bride | G7: 555-0201 | H7: lisa@email.com | I7: Ordered | J7: Necklace | K7: Giving speech
D8: Tom Brown | E8: Groomsman | F8: Groom | G8: 555-0202 | H8: tom@email.com | I8: Fitted | J8: Cufflinks
B9: PLANNING | D9: Rachel Green | E9: Bridesmaid | F9: Bride | G9: 555-0203 | H9: rachel@email.com | I9: Ordered | J9: Earrings
B10: Save the Date | D10: Mike Chen | E10: Groomsman | F10: Groom | G10: 555-0204 | H10: mike@email.com | I10: Pending | J10: Cufflinks
B11: Theme
B12: Calendar
B13: Timeline
B15: DAY OF
B16: Itinerary
B17: Packing List
B19: VENDORS & VENUE
B20: Vendors
B21: Venues
B22: Contacts
B24: FINANCES
B25: BUDGET
... B40: Gifts & Thanks

Sheet Food & Drinks
B2: =IF(SETUP!G6="","SET DATE",IF(SETUP!G6-TODAY()<0,"PAST DUE",SETUP!G6-TODAY()&" DAYS")) | D2: FOOD & DRINKS
B4: OVERVIEW | D4: MENU & CATERING TRACKER
B5: Instructions | D5: Item | E5: Category | F5: Quantity | G5: Unit Cost | H5: Total Cost | I5: Dietary | J5: Notes
B6: SETUP | D6: Chicken Parmesan | E6: Main Course | F6: 80 | G6: 35 | H6: =F6*G6 | I6: None | J6: Popular choice
B7: DASHBOARD | D7: Grilled Salmon | E7: Main Course | F7: 40 | G7: 42 | H7: =F7*G7 | I7: Pescatarian | J7: Fresh catch
D8: Mushroom Risotto | E8: Main Course | F8: 30 | G8: 28 | H8: =F8*G8 | I8: Vegetarian | J8: Vegan option avail
B9: PLANNING | D9: Champagne Toast | E9: Beverages | F9: 150 | G9: 8 | H9: =F9*G9 | I9: None | J9: Veuve Clicquot
B10: Save the Date | D10: House Wine (bottle) | E10: Beverages | F10: 50 | G10: 12 | H10: =F10*G10 | I10: None | J10: Red & white
B11: Theme | D11: Caesar Salad | E11: Appetizer | F11: 150 | G11: 5 | H11: =F11*G11 | I11: None | J11: Starter course
B12: Calendar | D12: Bruschetta | E12: Appetizer | F12: 100 | G12: 4 | H12: =F12*G12 | I12: Vegetarian | J12: Passed during cocktail hr
B13: Timeline | D13: TOTAL | H13: =SUM(H6:H12)
B15: DAY OF | D15: CATERING ANALYTICS
B16: Itinerary | D16: Category | E16: Total Cost | G16: Dietary Need | H16: Servings
B17: Packing List | D17: Main Course | E17: =SUMIF(E6:E12,"Main Course",H6:H12) | G17: None | H17: =SUMIF(I6:I12,"None",F6:F12)
D18: Beverages | E18: =SUMIF(E6:E12,"Beverages",H6:H12) | G18: Vegetarian | H18: =SUMIF(I6:I12,"Vegetarian",F6:F12)
B19: VENDORS & VENUE | D19: Appetizer | E19: =SUMIF(E6:E12,"Appetizer",H6:H12) | G19: Pescatarian | H19: =SUMIF(I6:I12,"Pescatarian",F6:F12)
B20: Vendors | G20: Vegan | H20: =SUMIF(I6:I12,"Vegan",F6:F12)
B21: Venues | G21: Gluten-Free | H21: =SUMIF(I6:I12,"Gluten-Free",F6:F12)
B22: Contacts
D23: CATERING COST BY CATEGORY | L23: DIETARY REQUIREMENTS BREAKDOWN
B24: FINANCES | D24: Distribution of food and beverage expenses across main courses, drinks, and appetizers | L24: Number of servings needed per dietary category — use this for final catering headcounts
B25: BUDGET
B26: Honeymoon
B28: GUESTS
B29: Guest List
B30: Seating Plan
B31: Wedding Party
B33: DETAILS
B34: Food & Drinks
B35: Music
B36: Photoshoot
B37: Photo Gallery
B39: GIFTS
B40: Gifts & Thanks

Sheet Photoshoot
B2: =IF(SETUP!G6="","SET DATE",IF(SETUP!G6-TODAY()<0,"PAST DUE",SETUP!G6-TODAY()&" DAYS")) | D2: PHOTO SHOT LIST
B4: OVERVIEW | D4: MUST-HAVE SHOTS
B5: Instructions | D5: Shot Description | E5: When | F5: Location | G5: People | H5: Priority | I5: Captured
B6: SETUP | D6: First look | E6: Pre-ceremony | F6: Garden | G6: Couple | H6: High | I6: No
B7: DASHBOARD | D7: Bride getting ready | E7: Morning | F7: Bridal suite | G7: Bride + bridesmaids | H7: High | I7: No
D8: Ring exchange close-up | E8: Ceremony | F8: Altar | G8: Couple | H8: High | I8: No
B9: PLANNING | D9: First kiss | E9: Ceremony | F9: Altar | G9: Couple | H9: High | I9: No
B10: Save the Date | D10: Full bridal party | E10: Post-ceremony | F10: Garden | G10: Full party | H10: High | I10: No
B11: Theme | D11: Family formals | E11: Post-ceremony | F11: Garden | G11: Families | H11: High | I11: No
B12: Calendar | D12: Couple sunset portraits | E12: Golden hour | F12: Garden | G12: Couple | H12: Medium | I12: No
B13: Timeline | D13: First dance | E13: Reception | F13: Dance floor | G13: Couple | H13: High | I13: No
D14: Cake cutting | E14: Reception | F14: Cake table | G14: Couple | H14: Medium | I14: No
B15: DAY OF | D15: Bouquet toss | E15: Reception | F15: Dance floor | G15: Bride + guests | H15: Low | I15: No
B16: Itinerary
B17: Packing List
B19: VENDORS & VENUE
B20: Vendors
B21: Venues
B22: Contacts
B24: FINANCES
B25: BUDGET
B26: Honeymoon
B28: GUESTS
B29: Guest List
B30: Seating Plan
... B40: Gifts & Thanks

Sheet Photo Gallery
B2: =IF(SETUP!G6="","SET DATE",IF(SETUP!G6-TODAY()<0,"PAST DUE",SETUP!G6-TODAY()&" DAYS")) | D2: INSPIRATION GALLERY
B4: OVERVIEW | D4: MOOD BOARD & REFERENCES
B5: Instructions | D5: Category | E5: Description | F5: Source / Link | G5: Notes
B6: SETUP | D6: Ceremony arch | E6: Greenery + white flowers arch | F6: Pinterest | G6: Similar to venue garden
B7: DASHBOARD | D7: Centerpieces | E7: Mixed greens with candles | F7: Instagram @florist | G7: Rustic style
D8: Cake design | E8: 3-tier naked cake with berries | F8: Pinterest | G8: Semi-naked preferred
B9: PLANNING | D9: Bouquet | E9: Loose garden-style, sage + blush | F9: Magazine clipping | G9: Show florist
B10: Save the Date | D10: Table setting | E10: Gold cutlery, linen napkins | F10: Pinterest | G10: Matches theme
B11: Theme
B12: Calendar
B13: Timeline
B15: DAY OF
B16: Itinerary
B17: Packing List
B19: VENDORS & VENUE
B20: Vendors
B21: Venues
B22: Contacts
B24: FINANCES
B25: BUDGET
... B40: Gifts & Thanks

Sheet Music
B2: =IF(SETUP!G6="","SET DATE",IF(SETUP!G6-TODAY()<0,"PAST DUE",SETUP!G6-TODAY()&" DAYS")) | D2: MUSIC & PLAYLIST
B4: OVERVIEW | D4: MUSIC SELECTIONS
B5: Instructions | D5: Moment | E5: Song Title | F5: Artist | G5: Category | H5: Notes
B6: SETUP | D6: Processional | E6: Canon in D | F6: Pachelbel | G6: Ceremony | H6: String quartet version
B7: DASHBOARD | D7: Bride entrance | E7: A Thousand Years | F7: Christina Perri | G7: Ceremony
D8: Recessional | E8: Signed, Sealed, Delivered | F8: Stevie Wonder | G8: Ceremony | H8: Upbeat exit
B9: PLANNING | D9: First dance | E9: Perfect | F9: Ed Sheeran | G9: Reception | H9: Practice needed
B10: Save the Date | D10: Father-daughter | E10: My Girl | F10: The Temptations | G10: Reception
B11: Theme | D11: Mother-son | E11: What a Wonderful World | F11: Louis Armstrong | G11: Reception
B12: Calendar | D12: Cake cutting | E12: You're My Best Friend | F12: Queen | G12: Reception
B13: Timeline | D13: Last dance | E13: Don't Stop Believin' | F13: Journey | G13: Reception | H13: Big finish!
B15: DAY OF | D15: DO NOT PLAY LIST
B16: Itinerary | D16: Song Title | E16: Artist | F16: Reason
B17: Packing List | D17: Chicken Dance | E17: Various | F17: Too cheesy
D18: Macarena | E18: Los del Rio | F18: Dated
B19: VENDORS & VENUE | D19: Electric Slide | E19: Marcia Griffiths | F19: Overplayed
B20: Vendors
B21: Venues
B22: Contacts
B24: FINANCES
B25: BUDGET
B26: Honeymoon
B28: GUESTS
B29: Guest List
B30: Seating Plan
B31: Wedding Party
B33: DETAILS
B34: Food & Drinks
... B40: Gifts & Thanks

Sheet Gifts & Thanks
B2: =IF(SETUP!G6="","SET DATE",IF(SETUP!G6-TODAY()<0,"PAST DUE",SETUP!G6-TODAY()&" DAYS")) | D2: GIFTS & THANK YOU TRACKER
B4: OVERVIEW | D4: GIFT LOG
B5: Instructions | D5: From | E5: Gift Description | F5: Estimated Value | G5: Date Received | H5: Thank You Status | I5: Date Sent | J5: Notes
B6: SETUP | D6: Emma Johnson | E6: KitchenAid Mixer | F6: 350 | G6: 2025-08-01 | H6: Sent | I6: 2025-08-10 | J6: Registry item
B7: DASHBOARD | D7: James Wilson | E7: Cash Gift | F7: 500 | G7: 2025-08-15 | H7: Sent | I7: 2025-08-20 | J7: Very generous
D8: Sophie Chen | E8: Dinnerware Set | F8: 200 | G8: 2025-08-20 | H8: Pending | J8: Beautiful set
B9: PLANNING | D9: The Garcia Family | E9: Spa Gift Card | F9: 150 | G9: 2025-09-15 | H9: Not Started | J9: Wedding day gift
B10: Save the Date | D10: Robert Taylor | E10: Wine Collection | F10: 120 | G10: 2025-09-01 | H10: Not Started | J10: Nice selection
B11: Theme
B12: Calendar | D12: TOTAL GIFTS | E12: =COUNTA(D6:D200) | F12: =SUM(F6:F200)
B13: Timeline
D14: THANK YOU PROGRESS
B15: DAY OF | D15: Status | E15: Count
B16: Itinerary | D16: Sent | E16: =COUNTIF(H6:H200,"Sent")
B17: Packing List | D17: Pending | E17: =COUNTIF(H6:H200,"Pending")
D18: Not Started | E18: =COUNTIF(H6:H200,"Not Started")
B19: VENDORS & VENUE
B20: Vendors | D20: THANK YOU CARD PROGRESS
B21: Venues | D21: Track which thank-you notes have been sent, are in progress, or still need to be written
B22: Contacts
B24: FINANCES
B25: BUDGET
B26: Honeymoon
B28: GUESTS
B29: Guest List
B30: Seating Plan
B31: Wedding Party
B33: DETAILS
B34: Food & Drinks
B35: Music
B36: Photoshoot
... B40: Gifts & Thanks

Sheet Honeymoon
B2: =IF(SETUP!G6="","SET DATE",IF(SETUP!G6-TODAY()<0,"PAST DUE",SETUP!G6-TODAY()&" DAYS")) | D2: HONEYMOON PLANNER
B4: OVERVIEW | D4: HONEYMOON DETAILS
B5: Instructions | D5: Destination | G5: Bali, Indonesia
B6: SETUP | D6: Travel Dates | G6: Sep 20 - Sep 27, 2025
B7: DASHBOARD | D7: Total Budget | G7: 8000
D8: Booking Status | G8: Partially Booked
B9: PLANNING
B10: Save the Date | D10: HONEYMOON BUDGET BREAKDOWN
B11: Theme | D11: Category | E11: Item | F11: Estimated | G11: Actual | H11: Booked | I11: Notes
B12: Calendar | D12: Transportation | E12: Round-trip flights | F12: 2000 | G12: 1850 | H12: Yes | I12: Direct flights
B13: Timeline | D13: Accommodation | E13: Hotel (7 nights) | F13: 3500 | G13: 3200 | H13: Yes | I13: Ocean view suite
D14: Entertainment | E14: Activities & tours | F14: 800 | G14: 0 | H14: No | I14: Snorkeling, temples
B15: DAY OF | D15: Food & Dining | E15: Meals (7 days) | F15: 1200 | G15: 0 | H15: No | I15: Resort + local
B16: Itinerary | D16: Insurance | E16: Travel insurance | F16: 200 | G16: 180 | H16: Yes | I16: Full coverage
B17: Packing List | D17: Shopping | E17: Souvenirs & gifts | F17: 300 | G17: 0 | H17: No
D18: TOTALS | F18: =SUM(F12:F17) | G18: =SUM(G12:G17)
B19: VENDORS & VENUE
B20: Vendors | D20: HONEYMOON COST ANALYSIS
B21: Venues | D21: Category | E21: Estimated | G21: Category | H21: Actual
B22: Contacts | D22: =D12 | E22: =F12 | G22: =D12 | H22: =G12
D23: =D13 | E23: =F13 | G23: =D13 | H23: =G13
B24: FINANCES | D24: =D14 | E24: =F14 | G24: =D14 | H24: =G14
B25: BUDGET | D25: =D15 | E25: =F15 | G25: =D15 | H25: =G15
B26: Honeymoon | D26: =D16 | E26: =F16 | G26: =D16 | H26: =G16
D27: =D17 | E27: =F17 | G27: =D17 | H27: =G17
B28: GUESTS
B29: Guest List | D29: HONEYMOON BUDGET ALLOCATION | L29: ESTIMATED VS ACTUAL HONEYMOON SPEND
B30: Seating Plan | D30: How your honeymoon budget is distributed across flights, hotel, activities, meals, and more | L30: Compare what you planned to spend against actual costs — adjust as you book each item
B31: Wedding Party
B33: DETAILS
B34: Food & Drinks
B35: Music
B36: Photoshoot
B37: Photo Gallery
B39: GIFTS
B40: Gifts & Thanks
